<sdf version='1.6'>
  <world name='racecar_tunnel'>
    <light name='sun' type='directional'>
      <cast_shadows>1</cast_shadows>
      <pose frame=''>0 0 10 0 -0 0</pose>
      <diffuse>0.8 0.8 0.8 1</diffuse>
      <specular>0.1 0.1 0.1 1</specular>
      <attenuation>
        <range>1000</range>
        <constant>0.9</constant>
        <linear>0.01</linear>
        <quadratic>0.001</quadratic>
      </attenuation>
      <direction>-0.5 0.5 -1</direction>
    </light>
    <model name='ground_plane'>
      <static>1</static>
      <link name='link'>
        <collision name='collision'>
          <geometry>
            <plane>
              <normal>0 0 1</normal>
              <size>150 150</size>
            </plane>
          </geometry>
          <surface>
            <friction>
              <ode>
                <mu>100</mu>
                <mu2>50</mu2>
              </ode>
              <torsional>
                <ode/>
              </torsional>
            </friction>
            <contact>
              <ode/>
            </contact>
            <bounce/>
          </surface>
          <max_contacts>10</max_contacts>
        </collision>
        <visual name='visual'>
          <cast_shadows>0</cast_shadows>
          <geometry>
            <plane>
              <normal>0 0 1</normal>
              <size>150 150</size>
            </plane>
          </geometry>
          <material>
            <script>
              <uri>file://media/materials/scripts/gazebo.material</uri>
              <name>Gazebo/Grass</name>
            </script>
          </material>
        </visual>
        <self_collide>0</self_collide>
        <kinematic>0</kinematic>
        <gravity>1</gravity>
      </link>
    </model>
    <gravity>0 0 -9.8</gravity>
    <magnetic_field>6e-06 2.3e-05 -4.2e-05</magnetic_field>
    <atmosphere type='adiabatic'/>
    <physics name='default_physics' default='0' type='ode'>
      <max_step_size>0.001</max_step_size>
      <real_time_factor>1</real_time_factor>
      <real_time_update_rate>1000</real_time_update_rate>
    </physics>
    <scene>
      <ambient>0.4 0.4 0.4 1</ambient>
      <background>0.7 0.7 0.7 1</background>
      <shadows>1</shadows>
    </scene>
    <spherical_coordinates>
      <surface_model>EARTH_WGS84</surface_model>
      <latitude_deg>0</latitude_deg>
      <longitude_deg>0</longitude_deg>
      <elevation>0</elevation>
      <heading_deg>0</heading_deg>
    </spherical_coordinates>
    <model name='roguetwo'>
      <link name='base_link'>
        <pose frame=''>0 0 0 0 -0 0</pose>
        <inertial>
          <pose frame=''>0.003589 -0.002381 0.001746 0 -0 0</pose>
          <mass>4.2</mass>
          <inertia>
            <ixx>0.0149378</ixx>
            <ixy>0.00196411</ixy>
            <ixz>-0.00199812</ixz>
            <iyy>0.030133</iyy>
            <iyz>0.000482542</iyz>
            <izz>0.0395525</izz>
          </inertia>
        </inertial>
        <collision name='base_link_fixed_joint_lump__chassis_collision'>
          <pose frame=''>0 0 -0.005 0 -0 0</pose>
          <geometry>
            <box>
              <size>0.258 0.168 0.01</size>
            </box>
          </geometry>
          <surface>
            <contact>
              <ode/>
            </contact>
            <friction>
              <ode/>
              <torsional>
                <ode/>
              </torsional>
            </friction>
            <bounce/>
          </surface>
          <max_contacts>10</max_contacts>
        </collision>
        <collision name='base_link_fixed_joint_lump__camera_stereo_left_collision_1'>
          <pose frame=''>0.2 0 0.05 0 -0 0</pose>
          <geometry>
            <box>
              <size>0.05 0.05 0.05</size>
            </box>
          </geometry>
          <surface>
            <contact>
              <ode/>
            </contact>
            <friction>
              <ode/>
              <torsional>
                <ode/>
              </torsional>
            </friction>
            <bounce/>
          </surface>
          <max_contacts>10</max_contacts>
        </collision>
        <collision name='base_link_fixed_joint_lump__camera_stereo_right_collision_2'>
          <pose frame=''>0.2 -0.1 0.05 0 -0 0</pose>
          <geometry>
            <box>
              <size>0.05 0.05 0.05</size>
            </box>
          </geometry>
          <surface>
            <contact>
              <ode/>
            </contact>
            <friction>
              <ode/>
              <torsional>
                <ode/>
              </torsional>
            </friction>
            <bounce/>
          </surface>
          <max_contacts>10</max_contacts>
        </collision>
        <collision name='base_link_fixed_joint_lump__left_battery_collision_3'>
          <pose frame=''>-0.025 0.057319 0.00052 0.349066 -0 0</pose>
          <geometry>
            <box>
              <size>0.16 0.047 0.024</size>
            </box>
          </geometry>
          <surface>
            <contact>
              <ode/>
            </contact>
            <friction>
              <ode/>
              <torsional>
                <ode/>
              </torsional>
            </friction>
            <bounce/>
          </surface>
          <max_contacts>10</max_contacts>
        </collision>
        <collision name='base_link_fixed_joint_lump__right_battery_collision_4'>
          <pose frame=''>-0.025 -0.057319 0.00052 -0.349066 0 0</pose>
          <geometry>
            <box>
              <size>0.16 0.047 0.024</size>
            </box>
          </geometry>
          <surface>
            <contact>
              <ode/>
            </contact>
            <friction>
              <ode/>
              <torsional>
                <ode/>
              </torsional>
            </friction>
            <bounce/>
          </surface>
          <max_contacts>10</max_contacts>
        </collision>
        <collision name='base_link_fixed_joint_lump__gps_collision_5'>
          <pose frame=''>0 0 0.1 0 -0 0</pose>
          <geometry>
            <box>
              <size>0.05 0.05 0.05</size>
            </box>
          </geometry>
          <max_contacts>10</max_contacts>
          <surface>
            <contact>
              <ode/>
            </contact>
            <bounce/>
            <friction>
              <torsional>
                <ode/>
              </torsional>
              <ode/>
            </friction>
          </surface>
        </collision>
        <collision name='base_link_fixed_joint_lump__imu_collision_6'>
          <pose frame=''>0 0 0 0 -0 0</pose>
          <geometry>
            <box>
              <size>0.05 0.05 0.05</size>
            </box>
          </geometry>
          <max_contacts>10</max_contacts>
          <surface>
            <contact>
              <ode/>
            </contact>
            <bounce/>
            <friction>
              <torsional>
                <ode/>
              </torsional>
              <ode/>
            </friction>
          </surface>
        </collision>
        <collision name='base_link_fixed_joint_lump__sonar1_link_collision_7'>
          <pose frame=''>0.25 0.15 0.15 0 -0 0</pose>
          <geometry>
            <box>
              <size>0.01 0.01 0.01</size>
            </box>
          </geometry>
          <surface>
            <contact>
              <ode/>
            </contact>
            <friction>
              <ode/>
              <torsional>
                <ode/>
              </torsional>
            </friction>
            <bounce/>
          </surface>
          <max_contacts>10</max_contacts>
        </collision>
        <collision name='base_link_fixed_joint_lump__sonar2_link_collision_8'>
          <pose frame=''>0 0.25 0.15 0 -0 1.1</pose>
          <geometry>
            <box>
              <size>0.01 0.01 0.01</size>
            </box>
          </geometry>
          <surface>
            <contact>
              <ode/>
            </contact>
            <friction>
              <ode/>
              <torsional>
                <ode/>
              </torsional>
            </friction>
            <bounce/>
          </surface>
          <max_contacts>10</max_contacts>
        </collision>
        <collision name='base_link_fixed_joint_lump__sonar3_link_collision_9'>
          <pose frame=''>0 -0.25 0.15 0 0 -1.1</pose>
          <geometry>
            <box>
              <size>0.01 0.01 0.01</size>
            </box>
          </geometry>
          <surface>
            <contact>
              <ode/>
            </contact>
            <friction>
              <ode/>
              <torsional>
                <ode/>
              </torsional>
            </friction>
            <bounce/>
          </surface>
          <max_contacts>10</max_contacts>
        </collision>
        <collision name='base_link_fixed_joint_lump__sonar4_link_collision_10'>
          <pose frame=''>-0.25 0 0.15 0 -0 3.14</pose>
          <geometry>
            <box>
              <size>0.01 0.01 0.01</size>
            </box>
          </geometry>
          <surface>
            <contact>
              <ode/>
            </contact>
            <friction>
              <ode/>
              <torsional>
                <ode/>
              </torsional>
            </friction>
            <bounce/>
          </surface>
          <max_contacts>10</max_contacts>
        </collision>
        <collision name='base_link_fixed_joint_lump__sonar5_link_collision_11'>
          <pose frame=''>0.25 -0.15 0.15 0 -0 0</pose>
          <geometry>
            <box>
              <size>0.01 0.01 0.01</size>
            </box>
          </geometry>
          <surface>
            <contact>
              <ode/>
            </contact>
            <friction>
              <ode/>
              <torsional>
                <ode/>
              </torsional>
            </friction>
            <bounce/>
          </surface>
          <max_contacts>10</max_contacts>
        </collision>
        <visual name='base_link_visual'>
          <pose frame=''>0 0 0 0 -0 0</pose>
          <geometry>
            <box>
              <size>0.01 0.01 0.01</size>
            </box>
          </geometry>
          <material>
            <script>
              <name>Gazebo/Grey</name>
              <uri>file://media/materials/scripts/gazebo.material</uri>
            </script>
          </material>
        </visual>
        <visual name='base_link_fixed_joint_lump__chassis_visual_1'>
          <pose frame=''>0 0 -0.005 0 -0 0</pose>
          <geometry>
            <box>
              <size>0.258 0.168 0.01</size>
            </box>
          </geometry>
          <material>
            <script>
              <name>Gazebo/Grey</name>
              <uri>file://media/materials/scripts/gazebo.material</uri>
            </script>
          </material>
        </visual>
        <visual name='base_link_fixed_joint_lump__camera_stereo_left_visual_2'>
          <pose frame=''>0.2 0 0.05 0 -0 0</pose>
          <geometry>
            <box>
              <size>0.05 0.05 0.05</size>
            </box>
          </geometry>
          <material>
            <script>
              <name>Gazebo/Green</name>
              <uri>file://media/materials/scripts/gazebo.material</uri>
            </script>
          </material>
        </visual>
        <visual name='base_link_fixed_joint_lump__camera_stereo_right_visual_3'>
          <pose frame=''>0.2 -0.1 0.05 0 -0 0</pose>
          <geometry>
            <box>
              <size>0.05 0.05 0.05</size>
            </box>
          </geometry>
          <material>
            <script>
              <name>Gazebo/Green</name>
              <uri>file://media/materials/scripts/gazebo.material</uri>
            </script>
          </material>
        </visual>
        <visual name='base_link_fixed_joint_lump__left_battery_visual_4'>
          <pose frame=''>-0.025 0.057319 0.00052 0.349066 -0 0</pose>
          <geometry>
            <box>
              <size>0.16 0.047 0.024</size>
            </box>
          </geometry>
          <material>
            <script>
              <name>Gazebo/Blue</name>
              <uri>file://media/materials/scripts/gazebo.material</uri>
            </script>
          </material>
        </visual>
        <visual name='base_link_fixed_joint_lump__right_battery_visual_5'>
          <pose frame=''>-0.025 -0.057319 0.00052 -0.349066 0 0</pose>
          <geometry>
            <box>
              <size>0.16 0.047 0.024</size>
            </box>
          </geometry>
          <material>
            <script>
              <name>Gazebo/Blue</name>
              <uri>file://media/materials/scripts/gazebo.material</uri>
            </script>
          </material>
        </visual>
        <visual name='base_link_fixed_joint_lump__gps_visual_6'>
          <pose frame=''>0 0 0.1 0 -0 0</pose>
          <geometry>
            <box>
              <size>0.05 0.05 0.05</size>
            </box>
          </geometry>
        </visual>
        <visual name='base_link_fixed_joint_lump__imu_visual_7'>
          <pose frame=''>0 0 0 0 -0 0</pose>
          <geometry>
            <box>
              <size>0.05 0.05 0.05</size>
            </box>
          </geometry>
        </visual>
        <visual name='base_link_fixed_joint_lump__sonar1_link_visual_8'>
          <pose frame=''>0.25 0.15 0.175 0 -0 0</pose>
          <geometry>
            <box>
              <size>0.05 0.05 0.05</size>
            </box>
          </geometry>
          <material>
            <script>
              <uri>__default__</uri>
              <name>__default__</name>
            </script>
          </material>
        </visual>
        <visual name='base_link_fixed_joint_lump__sonar2_link_visual_9'>
          <pose frame=''>0 0.25 0.175 0 -0 1.1</pose>
          <geometry>
            <box>
              <size>0.05 0.05 0.05</size>
            </box>
          </geometry>
          <material>
            <script>
              <uri>__default__</uri>
              <name>__default__</name>
            </script>
          </material>
        </visual>
        <visual name='base_link_fixed_joint_lump__sonar3_link_visual_10'>
          <pose frame=''>0 -0.25 0.175 0 0 -1.1</pose>
          <geometry>
            <box>
              <size>0.05 0.05 0.05</size>
            </box>
          </geometry>
          <material>
            <script>
              <uri>__default__</uri>
              <name>__default__</name>
            </script>
          </material>
        </visual>
        <visual name='base_link_fixed_joint_lump__sonar4_link_visual_11'>
          <pose frame=''>-0.25 0 0.175 0 -0 3.14</pose>
          <geometry>
            <box>
              <size>0.05 0.05 0.05</size>
            </box>
          </geometry>
          <material>
            <script>
              <uri>__default__</uri>
              <name>__default__</name>
            </script>
          </material>
        </visual>
        <visual name='base_link_fixed_joint_lump__sonar5_link_visual_12'>
          <pose frame=''>0.25 -0.15 0.175 0 -0 0</pose>
          <geometry>
            <box>
              <size>0.05 0.05 0.05</size>
            </box>
          </geometry>
          <material>
            <script>
              <uri>__default__</uri>
              <name>__default__</name>
            </script>
          </material>
        </visual>
        <velocity_decay/>
        <velocity_decay/>
        <velocity_decay/>
        <sensor name='camera_stereo_left' type='camera'>
          <update_rate>30</update_rate>
          <camera name='head'>
            <horizontal_fov>1.39626</horizontal_fov>
            <image>
              <width>640</width>
              <height>480</height>
              <format>R8G8B8</format>
            </image>
            <clip>
              <near>0.02</near>
              <far>300</far>
            </clip>
          </camera>
          <plugin name='camera_controller' filename='libgazebo_ros_camera.so'>
            <alwaysOn>true</alwaysOn>
            <updateRate>0.0</updateRate>
            <cameraName>rogue_two/camera_stereo_left</cameraName>
            <imageTopicName>image_raw</imageTopicName>
            <cameraInfoTopicName>camera_info</cameraInfoTopicName>
            <frameName>camera</frameName>
            <hackBaseline>0.07</hackBaseline>
            <distortionK1>0.0</distortionK1>
            <distortionK2>0.0</distortionK2>
            <distortionK3>0.0</distortionK3>
            <distortionT1>0.0</distortionT1>
            <distortionT2>0.0</distortionT2>
            <robotNamespace>/</robotNamespace>
          </plugin>
          <pose frame=''>0.2 0 0.05 0 -0 0</pose>
        </sensor>
        <velocity_decay/>
        <sensor name='camera_stereo_right' type='camera'>
          <update_rate>30</update_rate>
          <camera name='head'>
            <horizontal_fov>1.39626</horizontal_fov>
            <image>
              <width>640</width>
              <height>480</height>
              <format>R8G8B8</format>
            </image>
            <clip>
              <near>0.02</near>
              <far>300</far>
            </clip>
          </camera>
          <plugin name='camera_controller' filename='libgazebo_ros_camera.so'>
            <alwaysOn>true</alwaysOn>
            <updateRate>0.0</updateRate>
            <cameraName>rogue_two/camera_stereo_right</cameraName>
            <imageTopicName>image_raw</imageTopicName>
            <cameraInfoTopicName>camera_info</cameraInfoTopicName>
            <frameName>camera</frameName>
            <hackBaseline>0.07</hackBaseline>
            <distortionK1>0.0</distortionK1>
            <distortionK2>0.0</distortionK2>
            <distortionK3>0.0</distortionK3>
            <distortionT1>0.0</distortionT1>
            <distortionT2>0.0</distortionT2>
            <robotNamespace>/</robotNamespace>
          </plugin>
          <pose frame=''>0.2 -0.1 0.05 0 -0 0</pose>
        </sensor>
        <velocity_decay/>
        <velocity_decay/>
        <velocity_decay/>
        <sensor name='sonar1' type='ray'>
          <always_on>1</always_on>
          <update_rate>10</update_rate>
          <visualize>1</visualize>
          <ray>
            <scan>
              <horizontal>
                <samples>1</samples>
                <resolution>1</resolution>
                <min_angle>-0</min_angle>
                <max_angle>0</max_angle>
              </horizontal>
              <vertical>
                <samples>1</samples>
                <resolution>1</resolution>
                <min_angle>-0</min_angle>
                <max_angle>0</max_angle>
              </vertical>
            </scan>
            <range>
              <min>0.02</min>
              <max>4.5</max>
              <resolution>0.01</resolution>
            </range>
          </ray>
          <plugin name='gazebo_ros_sonar1_controller' filename='libhector_gazebo_ros_sonar.so'>
            <gaussianNoise>0.005</gaussianNoise>
            <topicName>/sonar_frontL_distance</topicName>
            <frameId>sonar1_link</frameId>
            <robotNamespace>/</robotNamespace>
          </plugin>
          <pose frame=''>0.25 0.15 0.15 0 -0 0</pose>
        </sensor>
        <velocity_decay/>
        <sensor name='sonar2' type='ray'>
          <always_on>1</always_on>
          <update_rate>10</update_rate>
          <visualize>1</visualize>
          <ray>
            <scan>
              <horizontal>
                <samples>1</samples>
                <resolution>1</resolution>
                <min_angle>-0</min_angle>
                <max_angle>0</max_angle>
              </horizontal>
              <vertical>
                <samples>1</samples>
                <resolution>1</resolution>
                <min_angle>-0</min_angle>
                <max_angle>0</max_angle>
              </vertical>
            </scan>
            <range>
              <min>0.02</min>
              <max>4.5</max>
              <resolution>0.01</resolution>
            </range>
          </ray>
          <plugin name='gazebo_ros_sonar2_controller' filename='libhector_gazebo_ros_sonar.so'>
            <gaussianNoise>0.005</gaussianNoise>
            <topicName>/sonar_left_distance</topicName>
            <bodyName>sonar</bodyName>
            <serviceName>sonar_service</serviceName>
            <frameId>sonar2_link</frameId>
            <robotNamespace>/</robotNamespace>
          </plugin>
          <pose frame=''>0 0.25 0.15 0 -0 1.1</pose>
        </sensor>
        <velocity_decay/>
        <sensor name='sonar3' type='ray'>
          <always_on>1</always_on>
          <update_rate>10</update_rate>
          <visualize>1</visualize>
          <ray>
            <scan>
              <horizontal>
                <samples>1</samples>
                <resolution>1</resolution>
                <min_angle>-0</min_angle>
                <max_angle>0</max_angle>
              </horizontal>
              <vertical>
                <samples>1</samples>
                <resolution>1</resolution>
                <min_angle>-0</min_angle>
                <max_angle>0</max_angle>
              </vertical>
            </scan>
            <range>
              <min>0.02</min>
              <max>4.5</max>
              <resolution>0.01</resolution>
            </range>
          </ray>
          <plugin name='gazebo_ros_sonar3_controller' filename='libhector_gazebo_ros_sonar.so'>
            <gaussianNoise>0.005</gaussianNoise>
            <topicName>/sonar_right_distance</topicName>
            <bodyName>sonar</bodyName>
            <serviceName>sonar_service</serviceName>
            <frameId>sonar3_link</frameId>
            <robotNamespace>/</robotNamespace>
          </plugin>
          <pose frame=''>0 -0.25 0.15 0 0 -1.1</pose>
        </sensor>
        <velocity_decay/>
        <sensor name='sonar4' type='ray'>
          <always_on>1</always_on>
          <update_rate>10</update_rate>
          <visualize>1</visualize>
          <ray>
            <scan>
              <horizontal>
                <samples>1</samples>
                <resolution>1</resolution>
                <min_angle>-0</min_angle>
                <max_angle>0</max_angle>
              </horizontal>
              <vertical>
                <samples>1</samples>
                <resolution>1</resolution>
                <min_angle>-0</min_angle>
                <max_angle>0</max_angle>
              </vertical>
            </scan>
            <range>
              <min>0.02</min>
              <max>4.5</max>
              <resolution>0.01</resolution>
            </range>
          </ray>
          <plugin name='gazebo_ros_sonar4_controller' filename='libhector_gazebo_ros_sonar.so'>
            <gaussianNoise>0.005</gaussianNoise>
            <topicName>/sonar_back_distance</topicName>
            <bodyName>sonar</bodyName>
            <serviceName>sonar_service</serviceName>
            <frameId>sonar4_link</frameId>
            <robotNamespace>/</robotNamespace>
          </plugin>
          <pose frame=''>-0.25 0 0.15 0 -0 3.14</pose>
        </sensor>
        <gravity>1</gravity>
        <velocity_decay/>
        <self_collide>0</self_collide>
        <sensor name='sonar5' type='ray'>
          <always_on>1</always_on>
          <update_rate>10</update_rate>
          <visualize>1</visualize>
          <ray>
            <scan>
              <horizontal>
                <samples>1</samples>
                <resolution>1</resolution>
                <min_angle>-0</min_angle>
                <max_angle>0</max_angle>
              </horizontal>
              <vertical>
                <samples>1</samples>
                <resolution>1</resolution>
                <min_angle>-0</min_angle>
                <max_angle>0</max_angle>
              </vertical>
            </scan>
            <range>
              <min>0.02</min>
              <max>4.5</max>
              <resolution>0.01</resolution>
            </range>
          </ray>
          <plugin name='gazebo_ros_sonar5_controller' filename='libhector_gazebo_ros_sonar.so'>
            <gaussianNoise>0.005</gaussianNoise>
            <topicName>/sonar_frontR_distance</topicName>
            <frameId>sonar5_link</frameId>
            <robotNamespace>/</robotNamespace>
          </plugin>
          <pose frame=''>0.25 -0.15 0.15 0 -0 0</pose>
        </sensor>
        <kinematic>0</kinematic>
      </link>
      <link name='left_steering_link'>
        <pose frame=''>0.1675 0.1525 -0.0235 0 -0 0</pose>
        <inertial>
          <pose frame=''>0 0 0 0 -0 0</pose>
          <mass>0.001</mass>
          <inertia>
            <ixx>0.001</ixx>
            <ixy>0</ixy>
            <ixz>0</ixz>
            <iyy>0.001</iyy>
            <iyz>0</iyz>
            <izz>0.001</izz>
          </inertia>
        </inertial>
        <self_collide>0</self_collide>
        <kinematic>0</kinematic>
        <gravity>1</gravity>
      </link>
      <joint name='left_front_shock' type='prismatic'>
        <child>left_steering_link</child>
        <parent>base_link</parent>
        <axis>
          <xyz>0 0 -1</xyz>
          <limit>
            <lower>-0.042</lower>
            <upper>0.042</upper>
            <effort>12.5106</effort>
            <velocity>1000</velocity>
          </limit>
          <dynamics>
            <spring_reference>0</spring_reference>
            <spring_stiffness>0</spring_stiffness>
          </dynamics>
          <use_parent_model_frame>1</use_parent_model_frame>
        </axis>
      </joint>
      <link name='left_front_axle_carrier'>
        <pose frame=''>0.1675 0.1525 -0.0235 0 -0 0</pose>
        <inertial>
          <pose frame=''>0 0 0 0 -0 0</pose>
          <mass>0.001</mass>
          <inertia>
            <ixx>0.001</ixx>
            <ixy>0</ixy>
            <ixz>0</ixz>
            <iyy>0.001</iyy>
            <iyz>0</iyz>
            <izz>0.001</izz>
          </inertia>
        </inertial>
        <self_collide>0</self_collide>
        <kinematic>0</kinematic>
        <gravity>1</gravity>
      </link>
      <joint name='left_steering_joint' type='revolute'>
        <child>left_front_axle_carrier</child>
        <parent>left_steering_link</parent>
        <axis>
          <xyz>0 0 1</xyz>
          <limit>
            <lower>-0.785398</lower>
            <upper>0.785398</upper>
            <effort>0.5649</effort>
            <velocity>4.553</velocity>
          </limit>
          <dynamics>
            <spring_reference>0</spring_reference>
            <spring_stiffness>0</spring_stiffness>
          </dynamics>
          <use_parent_model_frame>1</use_parent_model_frame>
        </axis>
      </joint>
      <link name='left_front_wheel'>
        <pose frame=''>0.1675 0.1525 -0.0235 1.5708 -0 0</pose>
        <inertial>
          <pose frame=''>0 0 0 0 -0 0</pose>
          <mass>0.29</mass>
          <inertia>
            <ixx>0.000746466</ixx>
            <ixy>0</ixy>
            <ixz>0</ixz>
            <iyy>0.000746466</iyy>
            <iyz>0</iyz>
            <izz>0.00111094</izz>
          </inertia>
        </inertial>
        <collision name='left_front_wheel_collision'>
          <pose frame=''>0 -0 0 0 -0 0</pose>
          <geometry>
            <cylinder>
              <length>0.0889</length>
              <radius>0.073025</radius>
            </cylinder>
          </geometry>
          <surface>
            <contact>
              <ode/>
            </contact>
            <friction>
              <ode/>
              <torsional>
                <ode/>
              </torsional>
            </friction>
            <bounce/>
          </surface>
          <max_contacts>10</max_contacts>
        </collision>
        <visual name='left_front_wheel_visual'>
          <pose frame=''>0 -0 0 0 -0 0</pose>
          <geometry>
            <cylinder>
              <length>0.0889</length>
              <radius>0.073025</radius>
            </cylinder>
          </geometry>
          <material>
            <script>
              <name>Gazebo/Black</name>
              <uri>file://media/materials/scripts/gazebo.material</uri>
            </script>
          </material>
        </visual>
        <gravity>1</gravity>
        <velocity_decay/>
        <self_collide>0</self_collide>
        <kinematic>0</kinematic>
      </link>
      <joint name='left_front_axle' type='revolute'>
        <child>left_front_wheel</child>
        <parent>left_front_axle_carrier</parent>
        <axis>
          <xyz>0 1 0</xyz>
          <limit>
            <lower>-1e+16</lower>
            <upper>1e+16</upper>
          </limit>
          <dynamics>
            <spring_reference>0</spring_reference>
            <spring_stiffness>0</spring_stiffness>
          </dynamics>
          <use_parent_model_frame>1</use_parent_model_frame>
        </axis>
      </joint>
      <link name='left_rear_axle_carrier'>
        <pose frame=''>-0.1675 0.1525 -0.0235 0 -0 0</pose>
        <inertial>
          <pose frame=''>0 0 0 0 -0 0</pose>
          <mass>0.001</mass>
          <inertia>
            <ixx>0.001</ixx>
            <ixy>0</ixy>
            <ixz>0</ixz>
            <iyy>0.001</iyy>
            <iyz>0</iyz>
            <izz>0.001</izz>
          </inertia>
        </inertial>
        <self_collide>0</self_collide>
        <kinematic>0</kinematic>
        <gravity>1</gravity>
      </link>
      <joint name='left_rear_shock' type='prismatic'>
        <child>left_rear_axle_carrier</child>
        <parent>base_link</parent>
        <axis>
          <xyz>0 0 -1</xyz>
          <limit>
            <lower>-0.042</lower>
            <upper>0.042</upper>
            <effort>12.5106</effort>
            <velocity>1000</velocity>
          </limit>
          <dynamics>
            <spring_reference>0</spring_reference>
            <spring_stiffness>0</spring_stiffness>
          </dynamics>
          <use_parent_model_frame>1</use_parent_model_frame>
        </axis>
      </joint>
      <link name='left_rear_wheel'>
        <pose frame=''>-0.1675 0.1525 -0.0235 1.5708 -0 0</pose>
        <inertial>
          <pose frame=''>0 0 0 0 -0 0</pose>
          <mass>0.29</mass>
          <inertia>
            <ixx>0.000746466</ixx>
            <ixy>0</ixy>
            <ixz>0</ixz>
            <iyy>0.000746466</iyy>
            <iyz>0</iyz>
            <izz>0.00111094</izz>
          </inertia>
        </inertial>
        <collision name='left_rear_wheel_collision'>
          <pose frame=''>0 -0 0 0 -0 0</pose>
          <geometry>
            <cylinder>
              <length>0.0889</length>
              <radius>0.073025</radius>
            </cylinder>
          </geometry>
          <surface>
            <contact>
              <ode/>
            </contact>
            <friction>
              <ode/>
              <torsional>
                <ode/>
              </torsional>
            </friction>
            <bounce/>
          </surface>
          <max_contacts>10</max_contacts>
        </collision>
        <visual name='left_rear_wheel_visual'>
          <pose frame=''>0 -0 0 0 -0 0</pose>
          <geometry>
            <cylinder>
              <length>0.0889</length>
              <radius>0.073025</radius>
            </cylinder>
          </geometry>
          <material>
            <script>
              <name>Gazebo/Black</name>
              <uri>file://media/materials/scripts/gazebo.material</uri>
            </script>
          </material>
        </visual>
        <gravity>1</gravity>
        <velocity_decay/>
        <self_collide>0</self_collide>
        <kinematic>0</kinematic>
      </link>
      <joint name='left_rear_axle' type='revolute'>
        <child>left_rear_wheel</child>
        <parent>left_rear_axle_carrier</parent>
        <axis>
          <xyz>0 1 0</xyz>
          <limit>
            <lower>-1e+16</lower>
            <upper>1e+16</upper>
          </limit>
          <dynamics>
            <spring_reference>0</spring_reference>
            <spring_stiffness>0</spring_stiffness>
          </dynamics>
          <use_parent_model_frame>1</use_parent_model_frame>
        </axis>
      </joint>
      <link name='right_steering_link'>
        <pose frame=''>0.1675 -0.1525 -0.0235 0 -0 0</pose>
        <inertial>
          <pose frame=''>0 0 0 0 -0 0</pose>
          <mass>0.001</mass>
          <inertia>
            <ixx>0.001</ixx>
            <ixy>0</ixy>
            <ixz>0</ixz>
            <iyy>0.001</iyy>
            <iyz>0</iyz>
            <izz>0.001</izz>
          </inertia>
        </inertial>
        <self_collide>0</self_collide>
        <kinematic>0</kinematic>
        <gravity>1</gravity>
      </link>
      <joint name='right_front_shock' type='prismatic'>
        <child>right_steering_link</child>
        <parent>base_link</parent>
        <axis>
          <xyz>0 0 -1</xyz>
          <limit>
            <lower>-0.042</lower>
            <upper>0.042</upper>
            <effort>12.5106</effort>
            <velocity>1000</velocity>
          </limit>
          <dynamics>
            <spring_reference>0</spring_reference>
            <spring_stiffness>0</spring_stiffness>
          </dynamics>
          <use_parent_model_frame>1</use_parent_model_frame>
        </axis>
      </joint>
      <link name='right_front_axle_carrier'>
        <pose frame=''>0.1675 -0.1525 -0.0235 0 -0 0</pose>
        <inertial>
          <pose frame=''>0 0 0 0 -0 0</pose>
          <mass>0.001</mass>
          <inertia>
            <ixx>0.001</ixx>
            <ixy>0</ixy>
            <ixz>0</ixz>
            <iyy>0.001</iyy>
            <iyz>0</iyz>
            <izz>0.001</izz>
          </inertia>
        </inertial>
        <self_collide>0</self_collide>
        <kinematic>0</kinematic>
        <gravity>1</gravity>
      </link>
      <joint name='right_steering_joint' type='revolute'>
        <child>right_front_axle_carrier</child>
        <parent>right_steering_link</parent>
        <axis>
          <xyz>0 0 1</xyz>
          <limit>
            <lower>-0.785398</lower>
            <upper>0.785398</upper>
            <effort>0.5649</effort>
            <velocity>4.553</velocity>
          </limit>
          <dynamics>
            <spring_reference>0</spring_reference>
            <spring_stiffness>0</spring_stiffness>
          </dynamics>
          <use_parent_model_frame>1</use_parent_model_frame>
        </axis>
      </joint>
      <link name='right_front_wheel'>
        <pose frame=''>0.1675 -0.1525 -0.0235 1.5708 -0 0</pose>
        <inertial>
          <pose frame=''>0 0 0 0 -0 0</pose>
          <mass>0.29</mass>
          <inertia>
            <ixx>0.000746466</ixx>
            <ixy>0</ixy>
            <ixz>0</ixz>
            <iyy>0.000746466</iyy>
            <iyz>0</iyz>
            <izz>0.00111094</izz>
          </inertia>
        </inertial>
        <collision name='right_front_wheel_collision'>
          <pose frame=''>0 0 0 0 -0 0</pose>
          <geometry>
            <cylinder>
              <length>0.0889</length>
              <radius>0.073025</radius>
            </cylinder>
          </geometry>
          <surface>
            <contact>
              <ode/>
            </contact>
            <friction>
              <ode/>
              <torsional>
                <ode/>
              </torsional>
            </friction>
            <bounce/>
          </surface>
          <max_contacts>10</max_contacts>
        </collision>
        <visual name='right_front_wheel_visual'>
          <pose frame=''>0 0 0 0 -0 0</pose>
          <geometry>
            <cylinder>
              <length>0.0889</length>
              <radius>0.073025</radius>
            </cylinder>
          </geometry>
          <material>
            <script>
              <name>Gazebo/Black</name>
              <uri>file://media/materials/scripts/gazebo.material</uri>
            </script>
          </material>
        </visual>
        <gravity>1</gravity>
        <velocity_decay/>
        <self_collide>0</self_collide>
        <kinematic>0</kinematic>
      </link>
      <joint name='right_front_axle' type='revolute'>
        <child>right_front_wheel</child>
        <parent>right_front_axle_carrier</parent>
        <axis>
          <xyz>0 1 0</xyz>
          <limit>
            <lower>-1e+16</lower>
            <upper>1e+16</upper>
          </limit>
          <dynamics>
            <spring_reference>0</spring_reference>
            <spring_stiffness>0</spring_stiffness>
          </dynamics>
          <use_parent_model_frame>1</use_parent_model_frame>
        </axis>
      </joint>
      <link name='right_rear_axle_carrier'>
        <pose frame=''>-0.1675 -0.1525 -0.0235 0 -0 0</pose>
        <inertial>
          <pose frame=''>0 0 0 0 -0 0</pose>
          <mass>0.001</mass>
          <inertia>
            <ixx>0.001</ixx>
            <ixy>0</ixy>
            <ixz>0</ixz>
            <iyy>0.001</iyy>
            <iyz>0</iyz>
            <izz>0.001</izz>
          </inertia>
        </inertial>
        <self_collide>0</self_collide>
        <kinematic>0</kinematic>
        <gravity>1</gravity>
      </link>
      <joint name='right_rear_shock' type='prismatic'>
        <child>right_rear_axle_carrier</child>
        <parent>base_link</parent>
        <axis>
          <xyz>0 0 -1</xyz>
          <limit>
            <lower>-0.042</lower>
            <upper>0.042</upper>
            <effort>12.5106</effort>
            <velocity>1000</velocity>
          </limit>
          <dynamics>
            <spring_reference>0</spring_reference>
            <spring_stiffness>0</spring_stiffness>
          </dynamics>
          <use_parent_model_frame>1</use_parent_model_frame>
        </axis>
      </joint>
      <link name='right_rear_wheel'>
        <pose frame=''>-0.1675 -0.1525 -0.0235 1.5708 -0 0</pose>
        <inertial>
          <pose frame=''>0 0 0 0 -0 0</pose>
          <mass>0.29</mass>
          <inertia>
            <ixx>0.000746466</ixx>
            <ixy>0</ixy>
            <ixz>0</ixz>
            <iyy>0.000746466</iyy>
            <iyz>0</iyz>
            <izz>0.00111094</izz>
          </inertia>
        </inertial>
        <collision name='right_rear_wheel_collision'>
          <pose frame=''>0 0 0 0 -0 0</pose>
          <geometry>
            <cylinder>
              <length>0.0889</length>
              <radius>0.073025</radius>
            </cylinder>
          </geometry>
          <surface>
            <contact>
              <ode/>
            </contact>
            <friction>
              <ode/>
              <torsional>
                <ode/>
              </torsional>
            </friction>
            <bounce/>
          </surface>
          <max_contacts>10</max_contacts>
        </collision>
        <visual name='right_rear_wheel_visual'>
          <pose frame=''>0 0 0 0 -0 0</pose>
          <geometry>
            <cylinder>
              <length>0.0889</length>
              <radius>0.073025</radius>
            </cylinder>
          </geometry>
          <material>
            <script>
              <name>Gazebo/Black</name>
              <uri>file://media/materials/scripts/gazebo.material</uri>
            </script>
          </material>
        </visual>
        <gravity>1</gravity>
        <velocity_decay/>
        <self_collide>0</self_collide>
        <kinematic>0</kinematic>
      </link>
      <joint name='right_rear_axle' type='revolute'>
        <child>right_rear_wheel</child>
        <parent>right_rear_axle_carrier</parent>
        <axis>
          <xyz>0 1 0</xyz>
          <limit>
            <lower>-1e+16</lower>
            <upper>1e+16</upper>
          </limit>
          <dynamics>
            <spring_reference>0</spring_reference>
            <spring_stiffness>0</spring_stiffness>
          </dynamics>
          <use_parent_model_frame>1</use_parent_model_frame>
        </axis>
      </joint>
      <plugin name='gazebo_ros_gps' filename='libhector_gazebo_ros_gps.so'>
        <updateRate>4.0</updateRate>
        <frameId>gps</frameId>
        <topicName>/gps/fix</topicName>
        <velocityTopicName>/gps/fix_velocity</velocityTopicName>
        <referenceLatitude>-30.06022459407145675</referenceLatitude>
        <referenceLongitude>-51.173913575780311191</referenceLongitude>
        <referenceHeading>90</referenceHeading>
        <referenceAltitude>10</referenceAltitude>
        <offset>0 0 0</offset>
        <drift>0.001 0.001 0.001</drift>
        <gaussianNoise>0.05 0.05 0.05</gaussianNoise>
        <velocityDrift>0.001 0.001 0.001</velocityDrift>
        <velocityGaussianNoise>0.5 0.5 0.5</velocityGaussianNoise>
        <robotNamespace>/</robotNamespace>
        <bodyName>base_link</bodyName>
        <xyzOffset>0 0 -0.1</xyzOffset>
        <rpyOffset>0 -0 0</rpyOffset>
      </plugin>
      <plugin name='imu_plugin' filename='libgazebo_ros_imu.so'>
        <alwaysOn>true</alwaysOn>
        <topicName>imu</topicName>
        <serviceName>imu_service</serviceName>
        <gaussianNoise>0.005</gaussianNoise>
        <updateRate>20.0</updateRate>
        <robotNamespace>/</robotNamespace>
        <bodyName>base_link</bodyName>
        <xyzOffset>0 0 0</xyzOffset>
        <rpyOffset>0 -0 0</rpyOffset>
      </plugin>
      <static>0</static>
      <plugin name='gazebo_ros_control' filename='libgazebo_ros_control.so'>
        <robotNamespace>/</robotNamespace>
      </plugin>
      <pose frame=''>0 0 0.1 0 -0 0</pose>
    </model>
    <model name='cardboard_box'>
      <pose frame=''>3.23059 -0.030262 0.15 0 -0 0</pose>
      <link name='link'>
        <inertial>
          <mass>2</mass>
          <inertia>
            <ixx>0.0416667</ixx>
            <ixy>0</ixy>
            <ixz>0</ixz>
            <iyy>0.0566667</iyy>
            <iyz>0</iyz>
            <izz>0.0683333</izz>
          </inertia>
        </inertial>
        <collision name='collision'>
          <geometry>
            <box>
              <size>0.5 0.4 0.3</size>
            </box>
          </geometry>
          <surface>
            <friction>
              <ode>
                <mu>1</mu>
                <mu2>1</mu2>
              </ode>
              <torsional>
                <ode/>
              </torsional>
            </friction>
            <contact>
              <ode>
                <kp>1e+07</kp>
                <kd>1</kd>
                <min_depth>0.001</min_depth>
                <max_vel>0.1</max_vel>
              </ode>
            </contact>
            <bounce/>
          </surface>
          <max_contacts>10</max_contacts>
        </collision>
        <visual name='visual'>
          <pose frame=''>0 0 -0.15 0 -0 0</pose>
          <geometry>
            <mesh>
              <uri>model://cardboard_box/meshes/cardboard_box.dae</uri>
              <scale>1 1 1</scale>
            </mesh>
          </geometry>
        </visual>
        <self_collide>0</self_collide>
        <kinematic>0</kinematic>
        <gravity>1</gravity>
      </link>
    </model>
    <model name='cardboard_box_0'>
      <pose frame=''>1.33702 -0.271359 0.15 0 -0 0</pose>
      <link name='link'>
        <inertial>
          <mass>2</mass>
          <inertia>
            <ixx>0.0416667</ixx>
            <ixy>0</ixy>
            <ixz>0</ixz>
            <iyy>0.0566667</iyy>
            <iyz>0</iyz>
            <izz>0.0683333</izz>
          </inertia>
        </inertial>
        <collision name='collision'>
          <geometry>
            <box>
              <size>0.5 0.4 0.3</size>
            </box>
          </geometry>
          <surface>
            <friction>
              <ode>
                <mu>1</mu>
                <mu2>1</mu2>
              </ode>
              <torsional>
                <ode/>
              </torsional>
            </friction>
            <contact>
              <ode>
                <kp>1e+07</kp>
                <kd>1</kd>
                <min_depth>0.001</min_depth>
                <max_vel>0.1</max_vel>
              </ode>
            </contact>
            <bounce/>
          </surface>
          <max_contacts>10</max_contacts>
        </collision>
        <visual name='visual'>
          <pose frame=''>0 0 -0.15 0 -0 0</pose>
          <geometry>
            <mesh>
              <uri>model://cardboard_box/meshes/cardboard_box.dae</uri>
              <scale>1 1 1</scale>
            </mesh>
          </geometry>
        </visual>
        <self_collide>0</self_collide>
        <kinematic>0</kinematic>
        <gravity>1</gravity>
      </link>
    </model>
    <model name='cardboard_box_1'>
      <pose frame=''>2.73056 -2.73573 0.15 0 -0 0</pose>
      <link name='link'>
        <inertial>
          <mass>2</mass>
          <inertia>
            <ixx>0.0416667</ixx>
            <ixy>0</ixy>
            <ixz>0</ixz>
            <iyy>0.0566667</iyy>
            <iyz>0</iyz>
            <izz>0.0683333</izz>
          </inertia>
        </inertial>
        <collision name='collision'>
          <geometry>
            <box>
              <size>0.5 0.4 0.3</size>
            </box>
          </geometry>
          <surface>
            <friction>
              <ode>
                <mu>1</mu>
                <mu2>1</mu2>
              </ode>
              <torsional>
                <ode/>
              </torsional>
            </friction>
            <contact>
              <ode>
                <kp>1e+07</kp>
                <kd>1</kd>
                <min_depth>0.001</min_depth>
                <max_vel>0.1</max_vel>
              </ode>
            </contact>
            <bounce/>
          </surface>
          <max_contacts>10</max_contacts>
        </collision>
        <visual name='visual'>
          <pose frame=''>0 0 -0.15 0 -0 0</pose>
          <geometry>
            <mesh>
              <uri>model://cardboard_box/meshes/cardboard_box.dae</uri>
              <scale>1 1 1</scale>
            </mesh>
          </geometry>
        </visual>
        <self_collide>0</self_collide>
        <kinematic>0</kinematic>
        <gravity>1</gravity>
      </link>
    </model>
    <model name='cardboard_box_2'>
      <pose frame=''>2.92881 2.00947 0.15 0 -0 0</pose>
      <link name='link'>
        <inertial>
          <mass>2</mass>
          <inertia>
            <ixx>0.0416667</ixx>
            <ixy>0</ixy>
            <ixz>0</ixz>
            <iyy>0.0566667</iyy>
            <iyz>0</iyz>
            <izz>0.0683333</izz>
          </inertia>
        </inertial>
        <collision name='collision'>
          <geometry>
            <box>
              <size>0.5 0.4 0.3</size>
            </box>
          </geometry>
          <surface>
            <friction>
              <ode>
                <mu>1</mu>
                <mu2>1</mu2>
              </ode>
              <torsional>
                <ode/>
              </torsional>
            </friction>
            <contact>
              <ode>
                <kp>1e+07</kp>
                <kd>1</kd>
                <min_depth>0.001</min_depth>
                <max_vel>0.1</max_vel>
              </ode>
            </contact>
            <bounce/>
          </surface>
          <max_contacts>10</max_contacts>
        </collision>
        <visual name='visual'>
          <pose frame=''>0 0 -0.15 0 -0 0</pose>
          <geometry>
            <mesh>
              <uri>model://cardboard_box/meshes/cardboard_box.dae</uri>
              <scale>1 1 1</scale>
            </mesh>
          </geometry>
        </visual>
        <self_collide>0</self_collide>
        <kinematic>0</kinematic>
        <gravity>1</gravity>
      </link>
    </model>
    <model name='cardboard_box_3'>
      <pose frame=''>4.8991 -1.93352 0.15 0 -0 0</pose>
      <link name='link'>
        <inertial>
          <mass>2</mass>
          <inertia>
            <ixx>0.0416667</ixx>
            <ixy>0</ixy>
            <ixz>0</ixz>
            <iyy>0.0566667</iyy>
            <iyz>0</iyz>
            <izz>0.0683333</izz>
          </inertia>
        </inertial>
        <collision name='collision'>
          <geometry>
            <box>
              <size>0.5 0.4 0.3</size>
            </box>
          </geometry>
          <surface>
            <friction>
              <ode>
                <mu>1</mu>
                <mu2>1</mu2>
              </ode>
              <torsional>
                <ode/>
              </torsional>
            </friction>
            <contact>
              <ode>
                <kp>1e+07</kp>
                <kd>1</kd>
                <min_depth>0.001</min_depth>
                <max_vel>0.1</max_vel>
              </ode>
            </contact>
            <bounce/>
          </surface>
          <max_contacts>10</max_contacts>
        </collision>
        <visual name='visual'>
          <pose frame=''>0 0 -0.15 0 -0 0</pose>
          <geometry>
            <mesh>
              <uri>model://cardboard_box/meshes/cardboard_box.dae</uri>
              <scale>1 1 1</scale>
            </mesh>
          </geometry>
        </visual>
        <self_collide>0</self_collide>
        <kinematic>0</kinematic>
        <gravity>1</gravity>
      </link>
    </model>
    <model name='cardboard_box_4'>
      <pose frame=''>4.9422 1.5724 0.15 0 -0 0</pose>
      <link name='link'>
        <inertial>
          <mass>2</mass>
          <inertia>
            <ixx>0.0416667</ixx>
            <ixy>0</ixy>
            <ixz>0</ixz>
            <iyy>0.0566667</iyy>
            <iyz>0</iyz>
            <izz>0.0683333</izz>
          </inertia>
        </inertial>
        <collision name='collision'>
          <geometry>
            <box>
              <size>0.5 0.4 0.3</size>
            </box>
          </geometry>
          <surface>
            <friction>
              <ode>
                <mu>1</mu>
                <mu2>1</mu2>
              </ode>
              <torsional>
                <ode/>
              </torsional>
            </friction>
            <contact>
              <ode>
                <kp>1e+07</kp>
                <kd>1</kd>
                <min_depth>0.001</min_depth>
                <max_vel>0.1</max_vel>
              </ode>
            </contact>
            <bounce/>
          </surface>
          <max_contacts>10</max_contacts>
        </collision>
        <visual name='visual'>
          <pose frame=''>0 0 -0.15 0 -0 0</pose>
          <geometry>
            <mesh>
              <uri>model://cardboard_box/meshes/cardboard_box.dae</uri>
              <scale>1 1 1</scale>
            </mesh>
          </geometry>
        </visual>
        <self_collide>0</self_collide>
        <kinematic>0</kinematic>
        <gravity>1</gravity>
      </link>
    </model>
    <model name='cardboard_box_5'>
      <pose frame=''>6.37187 0.051876 0.15 0 -0 0</pose>
      <link name='link'>
        <inertial>
          <mass>2</mass>
          <inertia>
            <ixx>0.0416667</ixx>
            <ixy>0</ixy>
            <ixz>0</ixz>
            <iyy>0.0566667</iyy>
            <iyz>0</iyz>
            <izz>0.0683333</izz>
          </inertia>
        </inertial>
        <collision name='collision'>
          <geometry>
            <box>
              <size>0.5 0.4 0.3</size>
            </box>
          </geometry>
          <surface>
            <friction>
              <ode>
                <mu>1</mu>
                <mu2>1</mu2>
              </ode>
              <torsional>
                <ode/>
              </torsional>
            </friction>
            <contact>
              <ode>
                <kp>1e+07</kp>
                <kd>1</kd>
                <min_depth>0.001</min_depth>
                <max_vel>0.1</max_vel>
              </ode>
            </contact>
            <bounce/>
          </surface>
          <max_contacts>10</max_contacts>
        </collision>
        <visual name='visual'>
          <pose frame=''>0 0 -0.15 0 -0 0</pose>
          <geometry>
            <mesh>
              <uri>model://cardboard_box/meshes/cardboard_box.dae</uri>
              <scale>1 1 1</scale>
            </mesh>
          </geometry>
        </visual>
        <self_collide>0</self_collide>
        <kinematic>0</kinematic>
        <gravity>1</gravity>
      </link>
    </model>
    <model name='cardboard_box_6'>
      <pose frame=''>7.4738 -2.52492 0.15 0 -0 0</pose>
      <link name='link'>
        <inertial>
          <mass>2</mass>
          <inertia>
            <ixx>0.0416667</ixx>
            <ixy>0</ixy>
            <ixz>0</ixz>
            <iyy>0.0566667</iyy>
            <iyz>0</iyz>
            <izz>0.0683333</izz>
          </inertia>
        </inertial>
        <collision name='collision'>
          <geometry>
            <box>
              <size>0.5 0.4 0.3</size>
            </box>
          </geometry>
          <surface>
            <friction>
              <ode>
                <mu>1</mu>
                <mu2>1</mu2>
              </ode>
              <torsional>
                <ode/>
              </torsional>
            </friction>
            <contact>
              <ode>
                <kp>1e+07</kp>
                <kd>1</kd>
                <min_depth>0.001</min_depth>
                <max_vel>0.1</max_vel>
              </ode>
            </contact>
            <bounce/>
          </surface>
          <max_contacts>10</max_contacts>
        </collision>
        <visual name='visual'>
          <pose frame=''>0 0 -0.15 0 -0 0</pose>
          <geometry>
            <mesh>
              <uri>model://cardboard_box/meshes/cardboard_box.dae</uri>
              <scale>1 1 1</scale>
            </mesh>
          </geometry>
        </visual>
        <self_collide>0</self_collide>
        <kinematic>0</kinematic>
        <gravity>1</gravity>
      </link>
    </model>
    <model name='cardboard_box_7'>
      <pose frame=''>7.71094 2.57969 0.15 0 -0 0</pose>
      <link name='link'>
        <inertial>
          <mass>2</mass>
          <inertia>
            <ixx>0.0416667</ixx>
            <ixy>0</ixy>
            <ixz>0</ixz>
            <iyy>0.0566667</iyy>
            <iyz>0</iyz>
            <izz>0.0683333</izz>
          </inertia>
        </inertial>
        <collision name='collision'>
          <geometry>
            <box>
              <size>0.5 0.4 0.3</size>
            </box>
          </geometry>
          <surface>
            <friction>
              <ode>
                <mu>1</mu>
                <mu2>1</mu2>
              </ode>
              <torsional>
                <ode/>
              </torsional>
            </friction>
            <contact>
              <ode>
                <kp>1e+07</kp>
                <kd>1</kd>
                <min_depth>0.001</min_depth>
                <max_vel>0.1</max_vel>
              </ode>
            </contact>
            <bounce/>
          </surface>
          <max_contacts>10</max_contacts>
        </collision>
        <visual name='visual'>
          <pose frame=''>0 0 -0.15 0 -0 0</pose>
          <geometry>
            <mesh>
              <uri>model://cardboard_box/meshes/cardboard_box.dae</uri>
              <scale>1 1 1</scale>
            </mesh>
          </geometry>
        </visual>
        <self_collide>0</self_collide>
        <kinematic>0</kinematic>
        <gravity>1</gravity>
      </link>
    </model>
    <model name='cardboard_box_8'>
      <pose frame=''>9.24137 3.05082 0.15 0 -0 0</pose>
      <link name='link'>
        <inertial>
          <mass>2</mass>
          <inertia>
            <ixx>0.0416667</ixx>
            <ixy>0</ixy>
            <ixz>0</ixz>
            <iyy>0.0566667</iyy>
            <iyz>0</iyz>
            <izz>0.0683333</izz>
          </inertia>
        </inertial>
        <collision name='collision'>
          <geometry>
            <box>
              <size>0.5 0.4 0.3</size>
            </box>
          </geometry>
          <surface>
            <friction>
              <ode>
                <mu>1</mu>
                <mu2>1</mu2>
              </ode>
              <torsional>
                <ode/>
              </torsional>
            </friction>
            <contact>
              <ode>
                <kp>1e+07</kp>
                <kd>1</kd>
                <min_depth>0.001</min_depth>
                <max_vel>0.1</max_vel>
              </ode>
            </contact>
            <bounce/>
          </surface>
          <max_contacts>10</max_contacts>
        </collision>
        <visual name='visual'>
          <pose frame=''>0 0 -0.15 0 -0 0</pose>
          <geometry>
            <mesh>
              <uri>model://cardboard_box/meshes/cardboard_box.dae</uri>
              <scale>1 1 1</scale>
            </mesh>
          </geometry>
        </visual>
        <self_collide>0</self_collide>
        <kinematic>0</kinematic>
        <gravity>1</gravity>
      </link>
    </model>
    <state world_name='racecar_tunnel'>
      <sim_time>2970 675000000</sim_time>
      <real_time>4295 892623305</real_time>
      <wall_time>1523067074 618995030</wall_time>
      <iterations>2970675</iterations>
      <model name='cardboard_box'>
        <pose frame=''>3.68388 0.09621 0.149 0 0 -0.155002</pose>
        <scale>1 1 1</scale>
        <link name='link'>
          <pose frame=''>3.68388 0.09621 0.149 0 0 -0.155002</pose>
          <velocity>0 0 0 0 -0 0</velocity>
          <acceleration>-3e-06 -1.9e-05 0 0.000126 -2.3e-05 0</acceleration>
          <wrench>-5e-06 -3.8e-05 1e-06 0 -0 0</wrench>
        </link>
      </model>
      <model name='cardboard_box_0'>
        <pose frame=''>1.66738 -0.356174 0.149 0 0 -0.495633</pose>
        <scale>1 1 1</scale>
        <link name='link'>
          <pose frame=''>1.66738 -0.356174 0.149 0 0 -0.495633</pose>
          <velocity>0 0 0 0 -0 0</velocity>
          <acceleration>7e-06 1.2e-05 0 -8.4e-05 5.8e-05 0</acceleration>
          <wrench>1.4e-05 2.5e-05 -1e-06 0 -0 0</wrench>
        </link>
      </model>
      <model name='cardboard_box_1'>
        <pose frame=''>2.73056 -2.73573 0.149 0 -0 0</pose>
        <scale>1 1 1</scale>
        <link name='link'>
          <pose frame=''>2.73056 -2.73573 0.149 0 -0 0</pose>
          <velocity>0 0 0 0 -0 0</velocity>
          <acceleration>0 -1.9e-05 0 0.000128 2e-06 0</acceleration>
          <wrench>1e-06 -3.8e-05 1e-06 0 -0 0</wrench>
        </link>
      </model>
      <model name='cardboard_box_2'>
        <pose frame=''>2.92881 2.00947 0.149 0 -0 0</pose>
        <scale>1 1 1</scale>
        <link name='link'>
          <pose frame=''>2.92881 2.00947 0.149 0 -0 0</pose>
          <velocity>0 0 0 0 -0 0</velocity>
          <acceleration>0 1.9e-05 0 -0.000128 -2e-06 0</acceleration>
          <wrench>-1e-06 3.8e-05 -1e-06 0 -0 0</wrench>
        </link>
      </model>
      <model name='cardboard_box_3'>
        <pose frame=''>4.8991 -1.93352 0.149 0 -0 0</pose>
        <scale>1 1 1</scale>
        <link name='link'>
          <pose frame=''>4.8991 -1.93352 0.149 0 -0 0</pose>
          <velocity>0 0 0 0 -0 0</velocity>
          <acceleration>0 -1.9e-05 0 0.000128 2e-06 0</acceleration>
          <wrench>1e-06 -3.8e-05 1e-06 0 -0 0</wrench>
        </link>
      </model>
      <model name='cardboard_box_4'>
        <pose frame=''>5.11616 1.8157 0.149 0 -0 0</pose>
        <scale>1 1 1</scale>
        <link name='link'>
          <pose frame=''>5.11616 1.8157 0.149 0 -0 0</pose>
          <velocity>0 0 0 0 -0 0</velocity>
          <acceleration>0 -1.9e-05 0 0.000128 2e-06 0</acceleration>
          <wrench>1e-06 -3.8e-05 1e-06 0 -0 0</wrench>
        </link>
      </model>
      <model name='cardboard_box_5'>
        <pose frame=''>6.37187 0.051876 0.149 0 -0 0</pose>
        <scale>1 1 1</scale>
        <link name='link'>
          <pose frame=''>6.37187 0.051876 0.149 0 -0 0</pose>
          <velocity>0 0 0 0 -0 0</velocity>
          <acceleration>0 -1.9e-05 0 0.000128 2e-06 0</acceleration>
          <wrench>1e-06 -3.8e-05 1e-06 0 -0 0</wrench>
        </link>
      </model>
      <model name='cardboard_box_6'>
        <pose frame=''>7.4738 -2.52492 0.149 0 -0 0</pose>
        <scale>1 1 1</scale>
        <link name='link'>
          <pose frame=''>7.4738 -2.52492 0.149 0 -0 0</pose>
          <velocity>0 0 0 0 -0 0</velocity>
          <acceleration>0 1.9e-05 0 -0.000128 -2e-06 0</acceleration>
          <wrench>-1e-06 3.8e-05 -1e-06 0 -0 0</wrench>
        </link>
      </model>
      <model name='cardboard_box_7'>
        <pose frame=''>7.71094 2.57969 0.149 0 -0 0</pose>
        <scale>1 1 1</scale>
        <link name='link'>
          <pose frame=''>7.71094 2.57969 0.149 0 -0 0</pose>
          <velocity>0 0 0 0 -0 0</velocity>
          <acceleration>0 -1.9e-05 0 0.000128 2e-06 0</acceleration>
          <wrench>1e-06 -3.8e-05 1e-06 0 -0 0</wrench>
        </link>
      </model>
      <model name='cardboard_box_8'>
        <pose frame=''>8.69548 0.063853 0.149 0 -0 0</pose>
        <scale>1 1 1</scale>
        <link name='link'>
          <pose frame=''>8.69548 0.063853 0.149 0 -0 0</pose>
          <velocity>0 0 0 0 -0 0</velocity>
          <acceleration>0 1.9e-05 0 -0.000128 -2e-06 0</acceleration>
          <wrench>-1e-06 3.8e-05 -1e-06 0 -0 0</wrench>
        </link>
      </model>
      <model name='ground_plane'>
        <pose frame=''>0 0 0 0 -0 0</pose>
        <scale>1 1 1</scale>
        <link name='link'>
          <pose frame=''>0 0 0 0 -0 0</pose>
          <velocity>0 0 0 0 -0 0</velocity>
          <acceleration>0 0 0 0 -0 0</acceleration>
          <wrench>0 0 0 0 -0 0</wrench>
        </link>
      </model>
      <model name='roguetwo'>
        <pose frame=''>10.4021 0.117084 0.100925 0.000389 0.002236 -1.54981</pose>
        <scale>1 1 1</scale>
        <link name='base_link'>
          <pose frame=''>10.4021 0.117084 0.100925 0.000389 0.002236 -1.54981</pose>
          <velocity>-7.1e-05 -0.000757 3.3e-05 0.011486 0.004709 -0.000358</velocity>
          <acceleration>0.001333 -6.8e-05 0.003827 0.136664 1.30612 2.10131</acceleration>
          <wrench>0.0056 -0.000287 0.016072 0 -0 0</wrench>
        </link>
        <link name='left_front_axle_carrier'>
          <pose frame=''>10.5581 -0.047111 0.073034 -0.000205 0.00226 -1.81344</pose>
          <velocity>-0.000274 -0.000955 0.00998 0.01015 -0.000717 -3.7e-05</velocity>
          <acceleration>0.111881 0.114775 52.6449 0.328154 -1.24477 -3.13583</acceleration>
          <wrench>0.000112 0.000115 0.052645 0 -0 0</wrench>
        </link>
        <link name='left_front_wheel'>
          <pose frame=''>10.5581 -0.047112 0.073034 -1.57055 0.604119 1.32829</pose>
          <velocity>-0.000305 -0.00087 0.009979 0.011918 -0.004175 -1.1e-05</velocity>
          <acceleration>0.066034 0.078734 52.6448 2.89761 0.400507 -1.50972</acceleration>
          <wrench>0.01915 0.022833 15.267 0 -0 0</wrench>
        </link>
        <link name='left_rear_axle_carrier'>
          <pose frame=''>10.5511 0.287813 0.072999 0.000389 0.002236 -1.54981</pose>
          <velocity>0.000894 -0.000933 -0.043203 0.011526 0.004821 -0.000479</velocity>
          <acceleration>-0.350847 0.01225 -52.7919 1.99334 -1.35701 -0.211849</acceleration>
          <wrench>-0.000351 1.2e-05 -0.052792 0 -0 0</wrench>
        </link>
        <link name='left_rear_wheel'>
          <pose frame=''>10.5511 0.287812 0.072999 -1.57206 1.26216 1.59057</pose>
          <velocity>0.000611 -0.000772 -0.043203 0.009684 0.004249 -0.000439</velocity>
          <acceleration>-0.284327 0.049738 -52.7918 1.56571 -1.40677 2.52927</acceleration>
          <wrench>-0.082455 0.014424 -15.3096 0 -0 0</wrench>
        </link>
        <link name='left_steering_link'>
          <pose frame=''>10.5581 -0.047114 0.073034 0.000391 0.002235 -1.54981</pose>
          <velocity>-0.000272 -0.000779 0.009982 0.010731 0.001545 -0.000388</velocity>
          <acceleration>-0.017038 0.029895 52.6445 0.91591 1.1888 -0.165326</acceleration>
          <wrench>-1.7e-05 3e-05 0.052645 0 -0 0</wrench>
        </link>
        <link name='right_front_axle_carrier'>
          <pose frame=''>10.2531 -0.053516 0.072999 -0.000388 0.002236 -1.89457</pose>
          <velocity>-0.000935 -0.000218 -0.043158 0.011656 0.005383 -0.00191</velocity>
          <acceleration>0.278247 -0.024742 -52.6445 1.94632 0.53928 1.18436</acceleration>
          <wrench>0.000278 -2.5e-05 -0.052645 0 -0 0</wrench>
        </link>
        <link name='right_front_wheel'>
          <pose frame=''>10.2531 -0.053516 0.072999 1.56995 -1.10265 -1.89381</pose>
          <velocity>-0.000855 -0.000218 -0.043158 0.013624 0.005797 -0.001914</velocity>
          <acceleration>0.198142 0.015451 -52.6445 -2.13534 1.36366 -2.8534</acceleration>
          <wrench>0.057461 0.004481 -15.2669 0 -0 0</wrench>
        </link>
        <link name='right_rear_axle_carrier'>
          <pose frame=''>10.2461 0.281411 0.073042 0.000389 0.002236 -1.54981</pose>
          <velocity>-0.000586 -0.000374 0.009511 0.011531 0.003558 -0.000504</velocity>
          <acceleration>-0.107591 -0.006743 52.792 -1.38569 -0.289299 2.93331</acceleration>
          <wrench>-0.000108 -7e-06 0.052792 0 -0 0</wrench>
        </link>
        <link name='right_rear_wheel'>
          <pose frame=''>10.2461 0.28141 0.073042 1.57118 0.030296 -1.5498</pose>
          <velocity>0.00098 -0.00045 0.009511 0.006171 0.013416 -5.2e-05</velocity>
          <acceleration>-0.118102 -0.096444 52.7916 1.63523 1.06008 -2.8484</acceleration>
          <wrench>-0.03425 -0.027969 15.3096 0 -0 0</wrench>
        </link>
        <link name='right_steering_link'>
          <pose frame=''>10.2531 -0.053516 0.072999 0.00039 0.002235 -1.54981</pose>
          <velocity>-0.000651 -0.000249 -0.043156 0.011624 0.005211 -0.000403</velocity>
          <acceleration>0.101515 0.066925 -52.6441 -2.57083 -1.46299 -0.182851</acceleration>
          <wrench>0.000102 6.7e-05 -0.052644 0 -0 0</wrench>
        </link>
      </model>
      <light name='sun'>
        <pose frame=''>0 0 10 0 -0 0</pose>
      </light>
    </state>
    <gui fullscreen='0'>
      <camera name='user_camera'>
        <pose frame=''>4.48846 1.32518 17.433 0.925127 1.57023 -2.21161</pose>
        <view_controller>orbit</view_controller>
        <projection_type>perspective</projection_type>
      </camera>
    </gui>
  </world>
</sdf>
