<sdf version='1.6'>
  <world name='racecar_tunnel'>
    <light name='sun' type='directional'>
      <cast_shadows>1</cast_shadows>
      <pose frame=''>0 0 10 0 -0 0</pose>
      <diffuse>0.8 0.8 0.8 1</diffuse>
      <specular>0.1 0.1 0.1 1</specular>
      <attenuation>
        <range>1000</range>
        <constant>0.9</constant>
        <linear>0.01</linear>
        <quadratic>0.001</quadratic>
      </attenuation>
      <direction>-0.5 0.5 -1</direction>
    </light>
    <model name='ground_plane'>
      <static>1</static>
      <link name='link'>
        <collision name='collision'>
          <geometry>
            <plane>
              <normal>0 0 1</normal>
              <size>150 150</size>
            </plane>
          </geometry>
          <surface>
            <friction>
              <ode>
                <mu>100</mu>
                <mu2>50</mu2>
              </ode>
              <torsional>
                <ode/>
              </torsional>
            </friction>
            <contact>
              <ode/>
            </contact>
            <bounce/>
          </surface>
          <max_contacts>10</max_contacts>
        </collision>
        <visual name='visual'>
          <cast_shadows>0</cast_shadows>
          <geometry>
            <plane>
              <normal>0 0 1</normal>
              <size>150 150</size>
            </plane>
          </geometry>
          <material>
            <script>
              <uri>file://media/materials/scripts/gazebo.material</uri>
              <name>Gazebo/Grass</name>
            </script>
          </material>
        </visual>
        <self_collide>0</self_collide>
        <kinematic>0</kinematic>
        <gravity>1</gravity>
      </link>
    </model>
    <gravity>0 0 -9.8</gravity>
    <magnetic_field>6e-06 2.3e-05 -4.2e-05</magnetic_field>
    <atmosphere type='adiabatic'/>
    <physics name='default_physics' default='0' type='ode'>
      <max_step_size>0.001</max_step_size>
      <real_time_factor>1</real_time_factor>
      <real_time_update_rate>1000</real_time_update_rate>
    </physics>
    <scene>
      <ambient>0.4 0.4 0.4 1</ambient>
      <background>0.7 0.7 0.7 1</background>
      <shadows>1</shadows>
    </scene>
    <spherical_coordinates>
      <surface_model>EARTH_WGS84</surface_model>
      <latitude_deg>0</latitude_deg>
      <longitude_deg>0</longitude_deg>
      <elevation>0</elevation>
      <heading_deg>0</heading_deg>
    </spherical_coordinates>
    <model name='roguetwo'>
      <link name='base_link'>
        <pose frame=''>0 0 0 0 -0 0</pose>
        <inertial>
          <pose frame=''>-0.001263 0 0.000532 0 -0 0</pose>
          <mass>4.099</mass>
          <inertia>
            <ixx>0.0136547</ixx>
            <ixy>-6.20385e-25</ixy>
            <ixz>-0.000989692</ixz>
            <iyy>0.0258562</iyy>
            <iyz>0</iyz>
            <izz>0.0345153</izz>
          </inertia>
        </inertial>
        <collision name='base_link_fixed_joint_lump__chassis_collision'>
          <pose frame=''>0 0 -0.005 0 -0 0</pose>
          <geometry>
            <box>
              <size>0.258 0.168 0.01</size>
            </box>
          </geometry>
          <surface>
            <contact>
              <ode/>
            </contact>
            <friction>
              <ode/>
              <torsional>
                <ode/>
              </torsional>
            </friction>
            <bounce/>
          </surface>
          <max_contacts>10</max_contacts>
        </collision>
        <collision name='base_link_fixed_joint_lump__camera_stereo_left_collision_1'>
          <pose frame=''>0.2 0 0.05 0 -0 0</pose>
          <geometry>
            <box>
              <size>0.05 0.05 0.05</size>
            </box>
          </geometry>
          <surface>
            <contact>
              <ode/>
            </contact>
            <friction>
              <ode/>
              <torsional>
                <ode/>
              </torsional>
            </friction>
            <bounce/>
          </surface>
          <max_contacts>10</max_contacts>
        </collision>
        <collision name='base_link_fixed_joint_lump__left_battery_collision_2'>
          <pose frame=''>-0.025 0.057319 0.00052 0.349066 -0 0</pose>
          <geometry>
            <box>
              <size>0.16 0.047 0.024</size>
            </box>
          </geometry>
          <surface>
            <contact>
              <ode/>
            </contact>
            <friction>
              <ode/>
              <torsional>
                <ode/>
              </torsional>
            </friction>
            <bounce/>
          </surface>
          <max_contacts>10</max_contacts>
        </collision>
        <collision name='base_link_fixed_joint_lump__right_battery_collision_3'>
          <pose frame=''>-0.025 -0.057319 0.00052 -0.349066 0 0</pose>
          <geometry>
            <box>
              <size>0.16 0.047 0.024</size>
            </box>
          </geometry>
          <surface>
            <contact>
              <ode/>
            </contact>
            <friction>
              <ode/>
              <torsional>
                <ode/>
              </torsional>
            </friction>
            <bounce/>
          </surface>
          <max_contacts>10</max_contacts>
        </collision>
        <collision name='base_link_fixed_joint_lump__gps_collision_4'>
          <pose frame=''>0 0 0.1 0 -0 0</pose>
          <geometry>
            <box>
              <size>0.05 0.05 0.05</size>
            </box>
          </geometry>
          <max_contacts>10</max_contacts>
          <surface>
            <contact>
              <ode/>
            </contact>
            <bounce/>
            <friction>
              <torsional>
                <ode/>
              </torsional>
              <ode/>
            </friction>
          </surface>
        </collision>
        <collision name='base_link_fixed_joint_lump__imu_collision_5'>
          <pose frame=''>0 0 0 0 -0 0</pose>
          <geometry>
            <box>
              <size>0.05 0.05 0.05</size>
            </box>
          </geometry>
          <max_contacts>10</max_contacts>
          <surface>
            <contact>
              <ode/>
            </contact>
            <bounce/>
            <friction>
              <torsional>
                <ode/>
              </torsional>
              <ode/>
            </friction>
          </surface>
        </collision>
        <collision name='base_link_fixed_joint_lump__sonar1_link_collision_6'>
          <pose frame=''>0.25 0 0.15 0 -0.55 0</pose>
          <geometry>
            <box>
              <size>0.01 0.01 0.01</size>
            </box>
          </geometry>
          <surface>
            <contact>
              <ode/>
            </contact>
            <friction>
              <ode/>
              <torsional>
                <ode/>
              </torsional>
            </friction>
            <bounce/>
          </surface>
          <max_contacts>10</max_contacts>
        </collision>
        <collision name='base_link_fixed_joint_lump__sonar2_link_collision_7'>
          <pose frame=''>0 0.25 0.15 0 -0.55 1.5</pose>
          <geometry>
            <box>
              <size>0.01 0.01 0.01</size>
            </box>
          </geometry>
          <surface>
            <contact>
              <ode/>
            </contact>
            <friction>
              <ode/>
              <torsional>
                <ode/>
              </torsional>
            </friction>
            <bounce/>
          </surface>
          <max_contacts>10</max_contacts>
        </collision>
        <collision name='base_link_fixed_joint_lump__sonar3_link_collision_8'>
          <pose frame=''>0 -0.25 0.15 0 -0.55 -1.5</pose>
          <geometry>
            <box>
              <size>0.01 0.01 0.01</size>
            </box>
          </geometry>
          <surface>
            <contact>
              <ode/>
            </contact>
            <friction>
              <ode/>
              <torsional>
                <ode/>
              </torsional>
            </friction>
            <bounce/>
          </surface>
          <max_contacts>10</max_contacts>
        </collision>
        <collision name='base_link_fixed_joint_lump__sonar4_link_collision_9'>
          <pose frame=''>-0.25 0 0.15 0 -0.55 3</pose>
          <geometry>
            <box>
              <size>0.01 0.01 0.01</size>
            </box>
          </geometry>
          <surface>
            <contact>
              <ode/>
            </contact>
            <friction>
              <ode/>
              <torsional>
                <ode/>
              </torsional>
            </friction>
            <bounce/>
          </surface>
          <max_contacts>10</max_contacts>
        </collision>
        <visual name='base_link_visual'>
          <pose frame=''>0 0 0 0 -0 0</pose>
          <geometry>
            <box>
              <size>0.01 0.01 0.01</size>
            </box>
          </geometry>
          <material>
            <script>
              <name>Gazebo/Grey</name>
              <uri>file://media/materials/scripts/gazebo.material</uri>
            </script>
          </material>
        </visual>
        <visual name='base_link_fixed_joint_lump__chassis_visual_1'>
          <pose frame=''>0 0 -0.005 0 -0 0</pose>
          <geometry>
            <box>
              <size>0.258 0.168 0.01</size>
            </box>
          </geometry>
          <material>
            <script>
              <name>Gazebo/Grey</name>
              <uri>file://media/materials/scripts/gazebo.material</uri>
            </script>
          </material>
        </visual>
        <visual name='base_link_fixed_joint_lump__camera_stereo_left_visual_2'>
          <pose frame=''>0.2 0 0.05 0 -0 0</pose>
          <geometry>
            <box>
              <size>0.05 0.05 0.05</size>
            </box>
          </geometry>
          <material>
            <script>
              <name>Gazebo/Green</name>
              <uri>file://media/materials/scripts/gazebo.material</uri>
            </script>
          </material>
        </visual>
        <visual name='base_link_fixed_joint_lump__left_battery_visual_3'>
          <pose frame=''>-0.025 0.057319 0.00052 0.349066 -0 0</pose>
          <geometry>
            <box>
              <size>0.16 0.047 0.024</size>
            </box>
          </geometry>
          <material>
            <script>
              <name>Gazebo/Blue</name>
              <uri>file://media/materials/scripts/gazebo.material</uri>
            </script>
          </material>
        </visual>
        <visual name='base_link_fixed_joint_lump__right_battery_visual_4'>
          <pose frame=''>-0.025 -0.057319 0.00052 -0.349066 0 0</pose>
          <geometry>
            <box>
              <size>0.16 0.047 0.024</size>
            </box>
          </geometry>
          <material>
            <script>
              <name>Gazebo/Blue</name>
              <uri>file://media/materials/scripts/gazebo.material</uri>
            </script>
          </material>
        </visual>
        <visual name='base_link_fixed_joint_lump__gps_visual_5'>
          <pose frame=''>0 0 0.1 0 -0 0</pose>
          <geometry>
            <box>
              <size>0.05 0.05 0.05</size>
            </box>
          </geometry>
        </visual>
        <visual name='base_link_fixed_joint_lump__imu_visual_6'>
          <pose frame=''>0 0 0 0 -0 0</pose>
          <geometry>
            <box>
              <size>0.05 0.05 0.05</size>
            </box>
          </geometry>
        </visual>
        <visual name='base_link_fixed_joint_lump__sonar1_link_visual_7'>
          <pose frame=''>0.236933 0 0.171313 0 -0.55 0</pose>
          <geometry>
            <box>
              <size>0.05 0.05 0.05</size>
            </box>
          </geometry>
          <material>
            <script>
              <uri>__default__</uri>
              <name>__default__</name>
            </script>
          </material>
        </visual>
        <visual name='base_link_fixed_joint_lump__sonar2_link_visual_8'>
          <pose frame=''>-0.000924 0.236966 0.171313 0 -0.55 1.5</pose>
          <geometry>
            <box>
              <size>0.05 0.05 0.05</size>
            </box>
          </geometry>
          <material>
            <script>
              <uri>__default__</uri>
              <name>__default__</name>
            </script>
          </material>
        </visual>
        <visual name='base_link_fixed_joint_lump__sonar3_link_visual_9'>
          <pose frame=''>-0.000924 -0.236966 0.171313 0 -0.55 -1.5</pose>
          <geometry>
            <box>
              <size>0.05 0.05 0.05</size>
            </box>
          </geometry>
          <material>
            <script>
              <uri>__default__</uri>
              <name>__default__</name>
            </script>
          </material>
        </visual>
        <visual name='base_link_fixed_joint_lump__sonar4_link_visual_10'>
          <pose frame=''>-0.237064 -0.001844 0.171313 0 -0.55 3</pose>
          <geometry>
            <box>
              <size>0.05 0.05 0.05</size>
            </box>
          </geometry>
          <material>
            <script>
              <uri>__default__</uri>
              <name>__default__</name>
            </script>
          </material>
        </visual>
        <velocity_decay/>
        <velocity_decay/>
        <velocity_decay/>
        <sensor name='camera_stereo_left' type='camera'>
          <update_rate>30</update_rate>
          <camera name='head'>
            <horizontal_fov>1.39626</horizontal_fov>
            <image>
              <width>640</width>
              <height>480</height>
              <format>R8G8B8</format>
            </image>
            <clip>
              <near>0.02</near>
              <far>300</far>
            </clip>
          </camera>
          <plugin name='camera_controller' filename='libgazebo_ros_camera.so'>
            <alwaysOn>true</alwaysOn>
            <updateRate>0.0</updateRate>
            <cameraName>rogue_two/camera_stereo_left</cameraName>
            <imageTopicName>image_raw</imageTopicName>
            <cameraInfoTopicName>camera_info</cameraInfoTopicName>
            <frameName>camera</frameName>
            <hackBaseline>0.07</hackBaseline>
            <distortionK1>0.0</distortionK1>
            <distortionK2>0.0</distortionK2>
            <distortionK3>0.0</distortionK3>
            <distortionT1>0.0</distortionT1>
            <distortionT2>0.0</distortionT2>
            <robotNamespace>/</robotNamespace>
          </plugin>
          <pose frame=''>0.2 0 0.05 0 -0 0</pose>
        </sensor>
        <velocity_decay/>
        <velocity_decay/>
        <velocity_decay/>
        <sensor name='sonar1' type='ray'>
          <always_on>1</always_on>
          <update_rate>10</update_rate>
          <visualize>1</visualize>
          <ray>
            <scan>
              <horizontal>
                <samples>2</samples>
                <resolution>1</resolution>
                <min_angle>-0.5</min_angle>
                <max_angle>0.5</max_angle>
              </horizontal>
              <vertical>
                <samples>2</samples>
                <resolution>1</resolution>
                <min_angle>-0.5</min_angle>
                <max_angle>0.5</max_angle>
              </vertical>
            </scan>
            <range>
              <min>0.02</min>
              <max>4.5</max>
              <resolution>0.01</resolution>
            </range>
          </ray>
          <plugin name='gazebo_ros_sonar1_controller' filename='libhector_gazebo_ros_sonar.so'>
            <gaussianNoise>0.005</gaussianNoise>
            <topicName>/sonar_front_distance</topicName>
            <frameId>sonar1_link</frameId>
            <robotNamespace>/</robotNamespace>
          </plugin>
          <pose frame=''>0.25 0 0.15 0 -0.55 0</pose>
        </sensor>
        <velocity_decay/>
        <sensor name='sonar2' type='ray'>
          <always_on>1</always_on>
          <update_rate>10</update_rate>
          <visualize>1</visualize>
          <ray>
            <scan>
              <horizontal>
                <samples>2</samples>
                <resolution>1</resolution>
                <min_angle>-0.5</min_angle>
                <max_angle>0.5</max_angle>
              </horizontal>
              <vertical>
                <samples>2</samples>
                <resolution>1</resolution>
                <min_angle>-0.5</min_angle>
                <max_angle>0.5</max_angle>
              </vertical>
            </scan>
            <range>
              <min>0.02</min>
              <max>4.5</max>
              <resolution>0.01</resolution>
            </range>
          </ray>
          <plugin name='gazebo_ros_sonar2_controller' filename='libhector_gazebo_ros_sonar.so'>
            <gaussianNoise>0.005</gaussianNoise>
            <topicName>/sonar_left_distance</topicName>
            <bodyName>sonar</bodyName>
            <serviceName>sonar_service</serviceName>
            <frameId>sonar2_link</frameId>
            <robotNamespace>/</robotNamespace>
          </plugin>
          <pose frame=''>0 0.25 0.15 0 -0.55 1.5</pose>
        </sensor>
        <velocity_decay/>
        <sensor name='sonar3' type='ray'>
          <always_on>1</always_on>
          <update_rate>10</update_rate>
          <visualize>1</visualize>
          <ray>
            <scan>
              <horizontal>
                <samples>2</samples>
                <resolution>1</resolution>
                <min_angle>-0.5</min_angle>
                <max_angle>0.5</max_angle>
              </horizontal>
              <vertical>
                <samples>2</samples>
                <resolution>1</resolution>
                <min_angle>-0.5</min_angle>
                <max_angle>0.5</max_angle>
              </vertical>
            </scan>
            <range>
              <min>0.02</min>
              <max>4.5</max>
              <resolution>0.01</resolution>
            </range>
          </ray>
          <plugin name='gazebo_ros_sonar3_controller' filename='libhector_gazebo_ros_sonar.so'>
            <gaussianNoise>0.005</gaussianNoise>
            <topicName>/sonar_right_distance</topicName>
            <bodyName>sonar</bodyName>
            <serviceName>sonar_service</serviceName>
            <frameId>sonar3_link</frameId>
            <robotNamespace>/</robotNamespace>
          </plugin>
          <pose frame=''>0 -0.25 0.15 0 -0.55 -1.5</pose>
        </sensor>
        <gravity>1</gravity>
        <velocity_decay/>
        <self_collide>0</self_collide>
        <sensor name='sonar4' type='ray'>
          <always_on>1</always_on>
          <update_rate>10</update_rate>
          <visualize>1</visualize>
          <ray>
            <scan>
              <horizontal>
                <samples>2</samples>
                <resolution>1</resolution>
                <min_angle>-0.5</min_angle>
                <max_angle>0.5</max_angle>
              </horizontal>
              <vertical>
                <samples>2</samples>
                <resolution>1</resolution>
                <min_angle>-0.5</min_angle>
                <max_angle>0.5</max_angle>
              </vertical>
            </scan>
            <range>
              <min>0.02</min>
              <max>4.5</max>
              <resolution>0.01</resolution>
            </range>
          </ray>
          <plugin name='gazebo_ros_sonar4_controller' filename='libhector_gazebo_ros_sonar.so'>
            <gaussianNoise>0.005</gaussianNoise>
            <topicName>/sonar_back_distance</topicName>
            <bodyName>sonar</bodyName>
            <serviceName>sonar_service</serviceName>
            <frameId>sonar4_link</frameId>
            <robotNamespace>/</robotNamespace>
          </plugin>
          <pose frame=''>-0.25 0 0.15 0 -0.55 3</pose>
        </sensor>
        <kinematic>0</kinematic>
      </link>
      <link name='left_steering_link'>
        <pose frame=''>0.1675 0.1525 -0.0235 0 -0 0</pose>
        <inertial>
          <pose frame=''>0 0 0 0 -0 0</pose>
          <mass>0.001</mass>
          <inertia>
            <ixx>0.001</ixx>
            <ixy>0</ixy>
            <ixz>0</ixz>
            <iyy>0.001</iyy>
            <iyz>0</iyz>
            <izz>0.001</izz>
          </inertia>
        </inertial>
        <self_collide>0</self_collide>
        <kinematic>0</kinematic>
        <gravity>1</gravity>
      </link>
      <joint name='left_front_shock' type='prismatic'>
        <child>left_steering_link</child>
        <parent>base_link</parent>
        <axis>
          <xyz>0 0 -1</xyz>
          <limit>
            <lower>-0.042</lower>
            <upper>0.042</upper>
            <effort>12.5106</effort>
            <velocity>1000</velocity>
          </limit>
          <dynamics>
            <spring_reference>0</spring_reference>
            <spring_stiffness>0</spring_stiffness>
          </dynamics>
          <use_parent_model_frame>1</use_parent_model_frame>
        </axis>
      </joint>
      <link name='left_front_axle_carrier'>
        <pose frame=''>0.1675 0.1525 -0.0235 0 -0 0</pose>
        <inertial>
          <pose frame=''>0 0 0 0 -0 0</pose>
          <mass>0.001</mass>
          <inertia>
            <ixx>0.001</ixx>
            <ixy>0</ixy>
            <ixz>0</ixz>
            <iyy>0.001</iyy>
            <iyz>0</iyz>
            <izz>0.001</izz>
          </inertia>
        </inertial>
        <self_collide>0</self_collide>
        <kinematic>0</kinematic>
        <gravity>1</gravity>
      </link>
      <joint name='left_steering_joint' type='revolute'>
        <child>left_front_axle_carrier</child>
        <parent>left_steering_link</parent>
        <axis>
          <xyz>0 0 1</xyz>
          <limit>
            <lower>-0.785398</lower>
            <upper>0.785398</upper>
            <effort>0.5649</effort>
            <velocity>4.553</velocity>
          </limit>
          <dynamics>
            <spring_reference>0</spring_reference>
            <spring_stiffness>0</spring_stiffness>
          </dynamics>
          <use_parent_model_frame>1</use_parent_model_frame>
        </axis>
      </joint>
      <link name='left_front_wheel'>
        <pose frame=''>0.1675 0.1525 -0.0235 1.5708 -0 0</pose>
        <inertial>
          <pose frame=''>0 0 0 0 -0 0</pose>
          <mass>0.29</mass>
          <inertia>
            <ixx>0.000746466</ixx>
            <ixy>0</ixy>
            <ixz>0</ixz>
            <iyy>0.000746466</iyy>
            <iyz>0</iyz>
            <izz>0.00111094</izz>
          </inertia>
        </inertial>
        <collision name='left_front_wheel_collision'>
          <pose frame=''>0 -0 0 0 -0 0</pose>
          <geometry>
            <cylinder>
              <length>0.0889</length>
              <radius>0.073025</radius>
            </cylinder>
          </geometry>
          <surface>
            <contact>
              <ode/>
            </contact>
            <friction>
              <ode/>
              <torsional>
                <ode/>
              </torsional>
            </friction>
            <bounce/>
          </surface>
          <max_contacts>10</max_contacts>
        </collision>
        <visual name='left_front_wheel_visual'>
          <pose frame=''>0 -0 0 0 -0 0</pose>
          <geometry>
            <cylinder>
              <length>0.0889</length>
              <radius>0.073025</radius>
            </cylinder>
          </geometry>
          <material>
            <script>
              <name>Gazebo/Black</name>
              <uri>file://media/materials/scripts/gazebo.material</uri>
            </script>
          </material>
        </visual>
        <gravity>1</gravity>
        <velocity_decay/>
        <self_collide>0</self_collide>
        <kinematic>0</kinematic>
      </link>
      <joint name='left_front_axle' type='revolute'>
        <child>left_front_wheel</child>
        <parent>left_front_axle_carrier</parent>
        <axis>
          <xyz>0 1 0</xyz>
          <limit>
            <lower>-1e+16</lower>
            <upper>1e+16</upper>
          </limit>
          <dynamics>
            <spring_reference>0</spring_reference>
            <spring_stiffness>0</spring_stiffness>
          </dynamics>
          <use_parent_model_frame>1</use_parent_model_frame>
        </axis>
      </joint>
      <link name='left_rear_axle_carrier'>
        <pose frame=''>-0.1675 0.1525 -0.0235 0 -0 0</pose>
        <inertial>
          <pose frame=''>0 0 0 0 -0 0</pose>
          <mass>0.001</mass>
          <inertia>
            <ixx>0.001</ixx>
            <ixy>0</ixy>
            <ixz>0</ixz>
            <iyy>0.001</iyy>
            <iyz>0</iyz>
            <izz>0.001</izz>
          </inertia>
        </inertial>
        <self_collide>0</self_collide>
        <kinematic>0</kinematic>
        <gravity>1</gravity>
      </link>
      <joint name='left_rear_shock' type='prismatic'>
        <child>left_rear_axle_carrier</child>
        <parent>base_link</parent>
        <axis>
          <xyz>0 0 -1</xyz>
          <limit>
            <lower>-0.042</lower>
            <upper>0.042</upper>
            <effort>12.5106</effort>
            <velocity>1000</velocity>
          </limit>
          <dynamics>
            <spring_reference>0</spring_reference>
            <spring_stiffness>0</spring_stiffness>
          </dynamics>
          <use_parent_model_frame>1</use_parent_model_frame>
        </axis>
      </joint>
      <link name='left_rear_wheel'>
        <pose frame=''>-0.1675 0.1525 -0.0235 1.5708 -0 0</pose>
        <inertial>
          <pose frame=''>0 0 0 0 -0 0</pose>
          <mass>0.29</mass>
          <inertia>
            <ixx>0.000746466</ixx>
            <ixy>0</ixy>
            <ixz>0</ixz>
            <iyy>0.000746466</iyy>
            <iyz>0</iyz>
            <izz>0.00111094</izz>
          </inertia>
        </inertial>
        <collision name='left_rear_wheel_collision'>
          <pose frame=''>0 -0 0 0 -0 0</pose>
          <geometry>
            <cylinder>
              <length>0.0889</length>
              <radius>0.073025</radius>
            </cylinder>
          </geometry>
          <surface>
            <contact>
              <ode/>
            </contact>
            <friction>
              <ode/>
              <torsional>
                <ode/>
              </torsional>
            </friction>
            <bounce/>
          </surface>
          <max_contacts>10</max_contacts>
        </collision>
        <visual name='left_rear_wheel_visual'>
          <pose frame=''>0 -0 0 0 -0 0</pose>
          <geometry>
            <cylinder>
              <length>0.0889</length>
              <radius>0.073025</radius>
            </cylinder>
          </geometry>
          <material>
            <script>
              <name>Gazebo/Black</name>
              <uri>file://media/materials/scripts/gazebo.material</uri>
            </script>
          </material>
        </visual>
        <gravity>1</gravity>
        <velocity_decay/>
        <self_collide>0</self_collide>
        <kinematic>0</kinematic>
      </link>
      <joint name='left_rear_axle' type='revolute'>
        <child>left_rear_wheel</child>
        <parent>left_rear_axle_carrier</parent>
        <axis>
          <xyz>0 1 0</xyz>
          <limit>
            <lower>-1e+16</lower>
            <upper>1e+16</upper>
          </limit>
          <dynamics>
            <spring_reference>0</spring_reference>
            <spring_stiffness>0</spring_stiffness>
          </dynamics>
          <use_parent_model_frame>1</use_parent_model_frame>
        </axis>
      </joint>
      <link name='right_steering_link'>
        <pose frame=''>0.1675 -0.1525 -0.0235 0 -0 0</pose>
        <inertial>
          <pose frame=''>0 0 0 0 -0 0</pose>
          <mass>0.001</mass>
          <inertia>
            <ixx>0.001</ixx>
            <ixy>0</ixy>
            <ixz>0</ixz>
            <iyy>0.001</iyy>
            <iyz>0</iyz>
            <izz>0.001</izz>
          </inertia>
        </inertial>
        <self_collide>0</self_collide>
        <kinematic>0</kinematic>
        <gravity>1</gravity>
      </link>
      <joint name='right_front_shock' type='prismatic'>
        <child>right_steering_link</child>
        <parent>base_link</parent>
        <axis>
          <xyz>0 0 -1</xyz>
          <limit>
            <lower>-0.042</lower>
            <upper>0.042</upper>
            <effort>12.5106</effort>
            <velocity>1000</velocity>
          </limit>
          <dynamics>
            <spring_reference>0</spring_reference>
            <spring_stiffness>0</spring_stiffness>
          </dynamics>
          <use_parent_model_frame>1</use_parent_model_frame>
        </axis>
      </joint>
      <link name='right_front_axle_carrier'>
        <pose frame=''>0.1675 -0.1525 -0.0235 0 -0 0</pose>
        <inertial>
          <pose frame=''>0 0 0 0 -0 0</pose>
          <mass>0.001</mass>
          <inertia>
            <ixx>0.001</ixx>
            <ixy>0</ixy>
            <ixz>0</ixz>
            <iyy>0.001</iyy>
            <iyz>0</iyz>
            <izz>0.001</izz>
          </inertia>
        </inertial>
        <self_collide>0</self_collide>
        <kinematic>0</kinematic>
        <gravity>1</gravity>
      </link>
      <joint name='right_steering_joint' type='revolute'>
        <child>right_front_axle_carrier</child>
        <parent>right_steering_link</parent>
        <axis>
          <xyz>0 0 1</xyz>
          <limit>
            <lower>-0.785398</lower>
            <upper>0.785398</upper>
            <effort>0.5649</effort>
            <velocity>4.553</velocity>
          </limit>
          <dynamics>
            <spring_reference>0</spring_reference>
            <spring_stiffness>0</spring_stiffness>
          </dynamics>
          <use_parent_model_frame>1</use_parent_model_frame>
        </axis>
      </joint>
      <link name='right_front_wheel'>
        <pose frame=''>0.1675 -0.1525 -0.0235 1.5708 -0 0</pose>
        <inertial>
          <pose frame=''>0 0 0 0 -0 0</pose>
          <mass>0.29</mass>
          <inertia>
            <ixx>0.000746466</ixx>
            <ixy>0</ixy>
            <ixz>0</ixz>
            <iyy>0.000746466</iyy>
            <iyz>0</iyz>
            <izz>0.00111094</izz>
          </inertia>
        </inertial>
        <collision name='right_front_wheel_collision'>
          <pose frame=''>0 0 0 0 -0 0</pose>
          <geometry>
            <cylinder>
              <length>0.0889</length>
              <radius>0.073025</radius>
            </cylinder>
          </geometry>
          <surface>
            <contact>
              <ode/>
            </contact>
            <friction>
              <ode/>
              <torsional>
                <ode/>
              </torsional>
            </friction>
            <bounce/>
          </surface>
          <max_contacts>10</max_contacts>
        </collision>
        <visual name='right_front_wheel_visual'>
          <pose frame=''>0 0 0 0 -0 0</pose>
          <geometry>
            <cylinder>
              <length>0.0889</length>
              <radius>0.073025</radius>
            </cylinder>
          </geometry>
          <material>
            <script>
              <name>Gazebo/Black</name>
              <uri>file://media/materials/scripts/gazebo.material</uri>
            </script>
          </material>
        </visual>
        <gravity>1</gravity>
        <velocity_decay/>
        <self_collide>0</self_collide>
        <kinematic>0</kinematic>
      </link>
      <joint name='right_front_axle' type='revolute'>
        <child>right_front_wheel</child>
        <parent>right_front_axle_carrier</parent>
        <axis>
          <xyz>0 1 0</xyz>
          <limit>
            <lower>-1e+16</lower>
            <upper>1e+16</upper>
          </limit>
          <dynamics>
            <spring_reference>0</spring_reference>
            <spring_stiffness>0</spring_stiffness>
          </dynamics>
          <use_parent_model_frame>1</use_parent_model_frame>
        </axis>
      </joint>
      <link name='right_rear_axle_carrier'>
        <pose frame=''>-0.1675 -0.1525 -0.0235 0 -0 0</pose>
        <inertial>
          <pose frame=''>0 0 0 0 -0 0</pose>
          <mass>0.001</mass>
          <inertia>
            <ixx>0.001</ixx>
            <ixy>0</ixy>
            <ixz>0</ixz>
            <iyy>0.001</iyy>
            <iyz>0</iyz>
            <izz>0.001</izz>
          </inertia>
        </inertial>
        <self_collide>0</self_collide>
        <kinematic>0</kinematic>
        <gravity>1</gravity>
      </link>
      <joint name='right_rear_shock' type='prismatic'>
        <child>right_rear_axle_carrier</child>
        <parent>base_link</parent>
        <axis>
          <xyz>0 0 -1</xyz>
          <limit>
            <lower>-0.042</lower>
            <upper>0.042</upper>
            <effort>12.5106</effort>
            <velocity>1000</velocity>
          </limit>
          <dynamics>
            <spring_reference>0</spring_reference>
            <spring_stiffness>0</spring_stiffness>
          </dynamics>
          <use_parent_model_frame>1</use_parent_model_frame>
        </axis>
      </joint>
      <link name='right_rear_wheel'>
        <pose frame=''>-0.1675 -0.1525 -0.0235 1.5708 -0 0</pose>
        <inertial>
          <pose frame=''>0 0 0 0 -0 0</pose>
          <mass>0.29</mass>
          <inertia>
            <ixx>0.000746466</ixx>
            <ixy>0</ixy>
            <ixz>0</ixz>
            <iyy>0.000746466</iyy>
            <iyz>0</iyz>
            <izz>0.00111094</izz>
          </inertia>
        </inertial>
        <collision name='right_rear_wheel_collision'>
          <pose frame=''>0 0 0 0 -0 0</pose>
          <geometry>
            <cylinder>
              <length>0.0889</length>
              <radius>0.073025</radius>
            </cylinder>
          </geometry>
          <surface>
            <contact>
              <ode/>
            </contact>
            <friction>
              <ode/>
              <torsional>
                <ode/>
              </torsional>
            </friction>
            <bounce/>
          </surface>
          <max_contacts>10</max_contacts>
        </collision>
        <visual name='right_rear_wheel_visual'>
          <pose frame=''>0 0 0 0 -0 0</pose>
          <geometry>
            <cylinder>
              <length>0.0889</length>
              <radius>0.073025</radius>
            </cylinder>
          </geometry>
          <material>
            <script>
              <name>Gazebo/Black</name>
              <uri>file://media/materials/scripts/gazebo.material</uri>
            </script>
          </material>
        </visual>
        <gravity>1</gravity>
        <velocity_decay/>
        <self_collide>0</self_collide>
        <kinematic>0</kinematic>
      </link>
      <joint name='right_rear_axle' type='revolute'>
        <child>right_rear_wheel</child>
        <parent>right_rear_axle_carrier</parent>
        <axis>
          <xyz>0 1 0</xyz>
          <limit>
            <lower>-1e+16</lower>
            <upper>1e+16</upper>
          </limit>
          <dynamics>
            <spring_reference>0</spring_reference>
            <spring_stiffness>0</spring_stiffness>
          </dynamics>
          <use_parent_model_frame>1</use_parent_model_frame>
        </axis>
      </joint>
      <plugin name='gazebo_ros_gps' filename='libhector_gazebo_ros_gps.so'>
        <updateRate>4.0</updateRate>
        <frameId>gps</frameId>
        <topicName>/gps/fix</topicName>
        <velocityTopicName>/gps/fix_velocity</velocityTopicName>
        <referenceLatitude>-30.06022459407145675</referenceLatitude>
        <referenceLongitude>-51.173913575780311191</referenceLongitude>
        <referenceHeading>90</referenceHeading>
        <referenceAltitude>10</referenceAltitude>
        <offset>0 0 0</offset>
        <drift>0.001 0.001 0.001</drift>
        <gaussianNoise>0.05 0.05 0.05</gaussianNoise>
        <velocityDrift>0.001 0.001 0.001</velocityDrift>
        <velocityGaussianNoise>0.5 0.5 0.5</velocityGaussianNoise>
        <robotNamespace>/</robotNamespace>
        <bodyName>base_link</bodyName>
        <xyzOffset>0 0 -0.1</xyzOffset>
        <rpyOffset>0 -0 0</rpyOffset>
      </plugin>
      <plugin name='imu_plugin' filename='libgazebo_ros_imu.so'>
        <alwaysOn>true</alwaysOn>
        <topicName>imu</topicName>
        <serviceName>imu_service</serviceName>
        <gaussianNoise>0.005</gaussianNoise>
        <updateRate>20.0</updateRate>
        <robotNamespace>/</robotNamespace>
        <bodyName>base_link</bodyName>
        <xyzOffset>0 0 0</xyzOffset>
        <rpyOffset>0 -0 0</rpyOffset>
      </plugin>
      <static>0</static>
      <plugin name='gazebo_ros_control' filename='libgazebo_ros_control.so'>
        <robotNamespace>/</robotNamespace>
      </plugin>
      <pose frame=''>0 0 0.1 0 -0 0</pose>
    </model>
    <model name='cardboard_box'>
      <pose frame=''>2.5049 -0.989085 0.15 0 -0 0</pose>
      <link name='link'>
        <inertial>
          <mass>2</mass>
          <inertia>
            <ixx>0.0416667</ixx>
            <ixy>0</ixy>
            <ixz>0</ixz>
            <iyy>0.0566667</iyy>
            <iyz>0</iyz>
            <izz>0.0683333</izz>
          </inertia>
        </inertial>
        <collision name='collision'>
          <geometry>
            <box>
              <size>0.5 0.4 0.3</size>
            </box>
          </geometry>
          <surface>
            <friction>
              <ode>
                <mu>1</mu>
                <mu2>1</mu2>
              </ode>
              <torsional>
                <ode/>
              </torsional>
            </friction>
            <contact>
              <ode>
                <kp>1e+07</kp>
                <kd>1</kd>
                <min_depth>0.001</min_depth>
                <max_vel>0.1</max_vel>
              </ode>
            </contact>
            <bounce/>
          </surface>
          <max_contacts>10</max_contacts>
        </collision>
        <visual name='visual'>
          <pose frame=''>0 0 -0.15 0 -0 0</pose>
          <geometry>
            <mesh>
              <uri>model://cardboard_box/meshes/cardboard_box.dae</uri>
              <scale>1 1 1</scale>
            </mesh>
          </geometry>
        </visual>
        <self_collide>0</self_collide>
        <kinematic>0</kinematic>
        <gravity>1</gravity>
      </link>
    </model>
    <model name='cardboard_box_0'>
      <pose frame=''>3.89563 -0.072571 0.15 0 -0 0</pose>
      <link name='link'>
        <inertial>
          <mass>2</mass>
          <inertia>
            <ixx>0.0416667</ixx>
            <ixy>0</ixy>
            <ixz>0</ixz>
            <iyy>0.0566667</iyy>
            <iyz>0</iyz>
            <izz>0.0683333</izz>
          </inertia>
        </inertial>
        <collision name='collision'>
          <geometry>
            <box>
              <size>0.5 0.4 0.3</size>
            </box>
          </geometry>
          <surface>
            <friction>
              <ode>
                <mu>1</mu>
                <mu2>1</mu2>
              </ode>
              <torsional>
                <ode/>
              </torsional>
            </friction>
            <contact>
              <ode>
                <kp>1e+07</kp>
                <kd>1</kd>
                <min_depth>0.001</min_depth>
                <max_vel>0.1</max_vel>
              </ode>
            </contact>
            <bounce/>
          </surface>
          <max_contacts>10</max_contacts>
        </collision>
        <visual name='visual'>
          <pose frame=''>0 0 -0.15 0 -0 0</pose>
          <geometry>
            <mesh>
              <uri>model://cardboard_box/meshes/cardboard_box.dae</uri>
              <scale>1 1 1</scale>
            </mesh>
          </geometry>
        </visual>
        <self_collide>0</self_collide>
        <kinematic>0</kinematic>
        <gravity>1</gravity>
      </link>
    </model>
    <model name='cardboard_box_1'>
      <pose frame=''>4.26875 1.70145 0.15 0 -0 0</pose>
      <link name='link'>
        <inertial>
          <mass>2</mass>
          <inertia>
            <ixx>0.0416667</ixx>
            <ixy>0</ixy>
            <ixz>0</ixz>
            <iyy>0.0566667</iyy>
            <iyz>0</iyz>
            <izz>0.0683333</izz>
          </inertia>
        </inertial>
        <collision name='collision'>
          <geometry>
            <box>
              <size>0.5 0.4 0.3</size>
            </box>
          </geometry>
          <surface>
            <friction>
              <ode>
                <mu>1</mu>
                <mu2>1</mu2>
              </ode>
              <torsional>
                <ode/>
              </torsional>
            </friction>
            <contact>
              <ode>
                <kp>1e+07</kp>
                <kd>1</kd>
                <min_depth>0.001</min_depth>
                <max_vel>0.1</max_vel>
              </ode>
            </contact>
            <bounce/>
          </surface>
          <max_contacts>10</max_contacts>
        </collision>
        <visual name='visual'>
          <pose frame=''>0 0 -0.15 0 -0 0</pose>
          <geometry>
            <mesh>
              <uri>model://cardboard_box/meshes/cardboard_box.dae</uri>
              <scale>1 1 1</scale>
            </mesh>
          </geometry>
        </visual>
        <self_collide>0</self_collide>
        <kinematic>0</kinematic>
        <gravity>1</gravity>
      </link>
    </model>
    <model name='cardboard_box_2'>
      <pose frame=''>4.50183 -1.68081 0.15 0 -0 0</pose>
      <link name='link'>
        <inertial>
          <mass>2</mass>
          <inertia>
            <ixx>0.0416667</ixx>
            <ixy>0</ixy>
            <ixz>0</ixz>
            <iyy>0.0566667</iyy>
            <iyz>0</iyz>
            <izz>0.0683333</izz>
          </inertia>
        </inertial>
        <collision name='collision'>
          <geometry>
            <box>
              <size>0.5 0.4 0.3</size>
            </box>
          </geometry>
          <surface>
            <friction>
              <ode>
                <mu>1</mu>
                <mu2>1</mu2>
              </ode>
              <torsional>
                <ode/>
              </torsional>
            </friction>
            <contact>
              <ode>
                <kp>1e+07</kp>
                <kd>1</kd>
                <min_depth>0.001</min_depth>
                <max_vel>0.1</max_vel>
              </ode>
            </contact>
            <bounce/>
          </surface>
          <max_contacts>10</max_contacts>
        </collision>
        <visual name='visual'>
          <pose frame=''>0 0 -0.15 0 -0 0</pose>
          <geometry>
            <mesh>
              <uri>model://cardboard_box/meshes/cardboard_box.dae</uri>
              <scale>1 1 1</scale>
            </mesh>
          </geometry>
        </visual>
        <self_collide>0</self_collide>
        <kinematic>0</kinematic>
        <gravity>1</gravity>
      </link>
    </model>
    <model name='cardboard_box_3'>
      <pose frame=''>5.99547 -1.08117 0.15 0 -0 0</pose>
      <link name='link'>
        <inertial>
          <mass>2</mass>
          <inertia>
            <ixx>0.0416667</ixx>
            <ixy>0</ixy>
            <ixz>0</ixz>
            <iyy>0.0566667</iyy>
            <iyz>0</iyz>
            <izz>0.0683333</izz>
          </inertia>
        </inertial>
        <collision name='collision'>
          <geometry>
            <box>
              <size>0.5 0.4 0.3</size>
            </box>
          </geometry>
          <surface>
            <friction>
              <ode>
                <mu>1</mu>
                <mu2>1</mu2>
              </ode>
              <torsional>
                <ode/>
              </torsional>
            </friction>
            <contact>
              <ode>
                <kp>1e+07</kp>
                <kd>1</kd>
                <min_depth>0.001</min_depth>
                <max_vel>0.1</max_vel>
              </ode>
            </contact>
            <bounce/>
          </surface>
          <max_contacts>10</max_contacts>
        </collision>
        <visual name='visual'>
          <pose frame=''>0 0 -0.15 0 -0 0</pose>
          <geometry>
            <mesh>
              <uri>model://cardboard_box/meshes/cardboard_box.dae</uri>
              <scale>1 1 1</scale>
            </mesh>
          </geometry>
        </visual>
        <self_collide>0</self_collide>
        <kinematic>0</kinematic>
        <gravity>1</gravity>
      </link>
    </model>
    <model name='cardboard_box_4'>
      <pose frame=''>6.05485 0.566503 0.15 0 -0 0</pose>
      <link name='link'>
        <inertial>
          <mass>2</mass>
          <inertia>
            <ixx>0.0416667</ixx>
            <ixy>0</ixy>
            <ixz>0</ixz>
            <iyy>0.0566667</iyy>
            <iyz>0</iyz>
            <izz>0.0683333</izz>
          </inertia>
        </inertial>
        <collision name='collision'>
          <geometry>
            <box>
              <size>0.5 0.4 0.3</size>
            </box>
          </geometry>
          <surface>
            <friction>
              <ode>
                <mu>1</mu>
                <mu2>1</mu2>
              </ode>
              <torsional>
                <ode/>
              </torsional>
            </friction>
            <contact>
              <ode>
                <kp>1e+07</kp>
                <kd>1</kd>
                <min_depth>0.001</min_depth>
                <max_vel>0.1</max_vel>
              </ode>
            </contact>
            <bounce/>
          </surface>
          <max_contacts>10</max_contacts>
        </collision>
        <visual name='visual'>
          <pose frame=''>0 0 -0.15 0 -0 0</pose>
          <geometry>
            <mesh>
              <uri>model://cardboard_box/meshes/cardboard_box.dae</uri>
              <scale>1 1 1</scale>
            </mesh>
          </geometry>
        </visual>
        <self_collide>0</self_collide>
        <kinematic>0</kinematic>
        <gravity>1</gravity>
      </link>
    </model>
    <model name='cardboard_box_5'>
      <pose frame=''>7.57833 -0.60518 0.15 0 -0 0</pose>
      <link name='link'>
        <inertial>
          <mass>2</mass>
          <inertia>
            <ixx>0.0416667</ixx>
            <ixy>0</ixy>
            <ixz>0</ixz>
            <iyy>0.0566667</iyy>
            <iyz>0</iyz>
            <izz>0.0683333</izz>
          </inertia>
        </inertial>
        <collision name='collision'>
          <geometry>
            <box>
              <size>0.5 0.4 0.3</size>
            </box>
          </geometry>
          <surface>
            <friction>
              <ode>
                <mu>1</mu>
                <mu2>1</mu2>
              </ode>
              <torsional>
                <ode/>
              </torsional>
            </friction>
            <contact>
              <ode>
                <kp>1e+07</kp>
                <kd>1</kd>
                <min_depth>0.001</min_depth>
                <max_vel>0.1</max_vel>
              </ode>
            </contact>
            <bounce/>
          </surface>
          <max_contacts>10</max_contacts>
        </collision>
        <visual name='visual'>
          <pose frame=''>0 0 -0.15 0 -0 0</pose>
          <geometry>
            <mesh>
              <uri>model://cardboard_box/meshes/cardboard_box.dae</uri>
              <scale>1 1 1</scale>
            </mesh>
          </geometry>
        </visual>
        <self_collide>0</self_collide>
        <kinematic>0</kinematic>
        <gravity>1</gravity>
      </link>
    </model>
    <model name='cardboard_box_6'>
      <pose frame=''>7.96062 -2.46459 0.15 0 -0 0</pose>
      <link name='link'>
        <inertial>
          <mass>2</mass>
          <inertia>
            <ixx>0.0416667</ixx>
            <ixy>0</ixy>
            <ixz>0</ixz>
            <iyy>0.0566667</iyy>
            <iyz>0</iyz>
            <izz>0.0683333</izz>
          </inertia>
        </inertial>
        <collision name='collision'>
          <geometry>
            <box>
              <size>0.5 0.4 0.3</size>
            </box>
          </geometry>
          <surface>
            <friction>
              <ode>
                <mu>1</mu>
                <mu2>1</mu2>
              </ode>
              <torsional>
                <ode/>
              </torsional>
            </friction>
            <contact>
              <ode>
                <kp>1e+07</kp>
                <kd>1</kd>
                <min_depth>0.001</min_depth>
                <max_vel>0.1</max_vel>
              </ode>
            </contact>
            <bounce/>
          </surface>
          <max_contacts>10</max_contacts>
        </collision>
        <visual name='visual'>
          <pose frame=''>0 0 -0.15 0 -0 0</pose>
          <geometry>
            <mesh>
              <uri>model://cardboard_box/meshes/cardboard_box.dae</uri>
              <scale>1 1 1</scale>
            </mesh>
          </geometry>
        </visual>
        <self_collide>0</self_collide>
        <kinematic>0</kinematic>
        <gravity>1</gravity>
      </link>
    </model>
    <model name='cardboard_box_7'>
      <pose frame=''>8.48646 0.957596 0.15 0 -0 0</pose>
      <link name='link'>
        <inertial>
          <mass>2</mass>
          <inertia>
            <ixx>0.0416667</ixx>
            <ixy>0</ixy>
            <ixz>0</ixz>
            <iyy>0.0566667</iyy>
            <iyz>0</iyz>
            <izz>0.0683333</izz>
          </inertia>
        </inertial>
        <collision name='collision'>
          <geometry>
            <box>
              <size>0.5 0.4 0.3</size>
            </box>
          </geometry>
          <surface>
            <friction>
              <ode>
                <mu>1</mu>
                <mu2>1</mu2>
              </ode>
              <torsional>
                <ode/>
              </torsional>
            </friction>
            <contact>
              <ode>
                <kp>1e+07</kp>
                <kd>1</kd>
                <min_depth>0.001</min_depth>
                <max_vel>0.1</max_vel>
              </ode>
            </contact>
            <bounce/>
          </surface>
          <max_contacts>10</max_contacts>
        </collision>
        <visual name='visual'>
          <pose frame=''>0 0 -0.15 0 -0 0</pose>
          <geometry>
            <mesh>
              <uri>model://cardboard_box/meshes/cardboard_box.dae</uri>
              <scale>1 1 1</scale>
            </mesh>
          </geometry>
        </visual>
        <self_collide>0</self_collide>
        <kinematic>0</kinematic>
        <gravity>1</gravity>
      </link>
    </model>
    <state world_name='racecar_tunnel'>
      <sim_time>77 994000000</sim_time>
      <real_time>92 767131325</real_time>
      <wall_time>1520208259 166404576</wall_time>
      <iterations>77994</iterations>
      <model name='cardboard_box'>
        <pose frame=''>2.5049 -0.989085 0.149 0 -0 0</pose>
        <scale>1 1 1</scale>
        <link name='link'>
          <pose frame=''>2.5049 -0.989085 0.149 0 -0 0</pose>
          <velocity>0 0 0 0 -0 0</velocity>
          <acceleration>0 -1.9e-05 0 0.000128 2e-06 0</acceleration>
          <wrench>1e-06 -3.8e-05 1e-06 0 -0 0</wrench>
        </link>
      </model>
      <model name='cardboard_box_0'>
        <pose frame=''>3.89563 -0.072571 0.149 0 -0 0</pose>
        <scale>1 1 1</scale>
        <link name='link'>
          <pose frame=''>3.89563 -0.072571 0.149 0 -0 0</pose>
          <velocity>0 0 0 0 -0 0</velocity>
          <acceleration>0 1.9e-05 0 -0.000128 -2e-06 0</acceleration>
          <wrench>-1e-06 3.8e-05 -1e-06 0 -0 0</wrench>
        </link>
      </model>
      <model name='cardboard_box_1'>
        <pose frame=''>4.26875 1.70145 0.149 0 -0 0</pose>
        <scale>1 1 1</scale>
        <link name='link'>
          <pose frame=''>4.26875 1.70145 0.149 0 -0 0</pose>
          <velocity>0 0 0 0 -0 0</velocity>
          <acceleration>0 -1.9e-05 0 0.000128 2e-06 0</acceleration>
          <wrench>1e-06 -3.8e-05 1e-06 0 -0 0</wrench>
        </link>
      </model>
      <model name='cardboard_box_2'>
        <pose frame=''>4.50183 -1.68081 0.149 0 -0 0</pose>
        <scale>1 1 1</scale>
        <link name='link'>
          <pose frame=''>4.50183 -1.68081 0.149 0 -0 0</pose>
          <velocity>0 0 0 0 -0 0</velocity>
          <acceleration>0 1.9e-05 0 -0.000128 -2e-06 0</acceleration>
          <wrench>-1e-06 3.8e-05 -1e-06 0 -0 0</wrench>
        </link>
      </model>
      <model name='cardboard_box_3'>
        <pose frame=''>5.99547 -1.08117 0.149 0 -0 0</pose>
        <scale>1 1 1</scale>
        <link name='link'>
          <pose frame=''>5.99547 -1.08117 0.149 0 -0 0</pose>
          <velocity>0 0 0 0 -0 0</velocity>
          <acceleration>0 -1.9e-05 0 0.000128 2e-06 0</acceleration>
          <wrench>1e-06 -3.8e-05 1e-06 0 -0 0</wrench>
        </link>
      </model>
      <model name='cardboard_box_4'>
        <pose frame=''>6.05485 0.566503 0.149 0 -0 0</pose>
        <scale>1 1 1</scale>
        <link name='link'>
          <pose frame=''>6.05485 0.566503 0.149 0 -0 0</pose>
          <velocity>0 0 0 0 -0 0</velocity>
          <acceleration>0 1.9e-05 0 -0.000128 -2e-06 0</acceleration>
          <wrench>-1e-06 3.8e-05 -1e-06 0 -0 0</wrench>
        </link>
      </model>
      <model name='cardboard_box_5'>
        <pose frame=''>7.57833 -0.60518 0.149 0 -0 0</pose>
        <scale>1 1 1</scale>
        <link name='link'>
          <pose frame=''>7.57833 -0.60518 0.149 0 -0 0</pose>
          <velocity>0 0 0 0 -0 0</velocity>
          <acceleration>0 -1.9e-05 0 0.000128 2e-06 0</acceleration>
          <wrench>1e-06 -3.8e-05 1e-06 0 -0 0</wrench>
        </link>
      </model>
      <model name='cardboard_box_6'>
        <pose frame=''>7.96062 -2.46459 0.149021 2e-06 -2e-06 -0</pose>
        <scale>1 1 1</scale>
        <link name='link'>
          <pose frame=''>7.96062 -2.46459 0.149021 2e-06 -2e-06 -0</pose>
          <velocity>0 0 0 0 -0 0</velocity>
          <acceleration>0 -1.1e-05 0 7.6e-05 -1e-06 0</acceleration>
          <wrench>0 -2.3e-05 -1e-06 0 -0 0</wrench>
        </link>
      </model>
      <model name='cardboard_box_7'>
        <pose frame=''>8.48646 0.957596 0.14951 2e-06 -2e-06 -0</pose>
        <scale>1 1 1</scale>
        <link name='link'>
          <pose frame=''>8.48646 0.957596 0.14951 2e-06 -2e-06 -0</pose>
          <velocity>0 0 0 0 -0 0</velocity>
          <acceleration>0 1.1e-05 0 -7.2e-05 1e-06 0</acceleration>
          <wrench>0 2.2e-05 0 0 -0 0</wrench>
        </link>
      </model>
      <model name='ground_plane'>
        <pose frame=''>0 0 0 0 -0 0</pose>
        <scale>1 1 1</scale>
        <link name='link'>
          <pose frame=''>0 0 0 0 -0 0</pose>
          <velocity>0 0 0 0 -0 0</velocity>
          <acceleration>0 0 0 0 -0 0</acceleration>
          <wrench>0 0 0 0 -0 0</wrench>
        </link>
      </model>
      <model name='roguetwo'>
        <pose frame=''>0.004387 0.000137 0.10481 5.4e-05 -0.001574 -0.001104</pose>
        <scale>1 1 1</scale>
        <link name='base_link'>
          <pose frame=''>0.004387 0.000137 0.10481 5.4e-05 -0.001574 -0.001104</pose>
          <velocity>7.1e-05 -0.000105 0.000136 0.084534 -8e-06 0.002822</velocity>
          <acceleration>-0.000599 -0.479892 0.27263 -2.30751 0.052084 -2.82886</acceleration>
          <wrench>-0.002457 -1.96708 1.11751 0 -0 0</wrench>
        </link>
        <link name='left_front_axle_carrier'>
          <pose frame=''>0.172098 0.152447 0.073022 5.4e-05 -0.001574 -0.001064</pose>
          <velocity>0.000152 -0.007941 -0.003737 0.084234 -1.2e-05 0.002539</velocity>
          <acceleration>0.08963 -5.05527 -7.42927 -2.55503 0.079568 2.04703</acceleration>
          <wrench>9e-05 -0.005055 -0.007429 0 -0 0</wrench>
        </link>
        <link name='left_front_wheel'>
          <pose frame=''>0.172099 0.152449 0.073022 1.57085 0.006603 -0.001063</pose>
          <velocity>7.5e-05 -0.006054 -0.003736 0.082922 -0.00055 0.002589</velocity>
          <acceleration>-0.008464 -3.87374 -7.42681 -0.341608 0.800503 -0.160788</acceleration>
          <wrench>-0.002455 -1.12338 -2.15377 0 -0 0</wrench>
        </link>
        <link name='left_rear_axle_carrier'>
          <pose frame=''>-0.16289 0.152814 0.073022 5.3e-05 -0.001574 -0.001104</pose>
          <velocity>0.000266 -0.009151 -0.003689 0.083855 -1.8e-05 0.003663</velocity>
          <acceleration>0.162001 -5.66954 -7.41453 -2.65218 0.074909 -2.41997</acceleration>
          <wrench>0.000162 -0.00567 -0.007415 0 -0 0</wrench>
        </link>
        <link name='left_rear_wheel'>
          <pose frame=''>-0.162891 0.152817 0.073022 1.57085 -0.01143 -0.001104</pose>
          <velocity>6.7e-05 -0.0059 -0.003687 0.080858 -0.001225 0.003527</velocity>
          <acceleration>-0.041508 -3.81902 -7.41108 2.07451 -0.125242 -0.605474</acceleration>
          <wrench>-0.012037 -1.10752 -2.14921 0 -0 0</wrench>
        </link>
        <link name='left_steering_link'>
          <pose frame=''>0.172101 0.15245 0.073022 5.4e-05 -0.001574 -0.001104</pose>
          <velocity>-3e-05 -0.003435 -0.003741 0.084397 -1.2e-05 0.002291</velocity>
          <acceleration>-0.141934 -2.22388 -7.43712 -2.43552 0.079559 3.04743</acceleration>
          <wrench>-0.000142 -0.002224 -0.007437 0 -0 0</wrench>
        </link>
        <link name='right_front_axle_carrier'>
          <pose frame=''>0.171761 -0.152553 0.073022 5.4e-05 -0.001574 -0.001133</pose>
          <velocity>-1.5e-05 -0.007964 -0.003736 0.084353 -3e-06 0.002502</velocity>
          <acceleration>-0.068082 -5.10247 -7.41975 -2.39845 0.091198 1.98402</acceleration>
          <wrench>-6.8e-05 -0.005102 -0.00742 0 -0 0</wrench>
        </link>
        <link name='right_front_wheel'>
          <pose frame=''>0.171762 -0.152552 0.073022 1.57085 0.002385 -0.001132</pose>
          <velocity>6.5e-05 -0.006069 -0.003734 0.083126 -0.000683 0.002579</velocity>
          <acceleration>0.029303 -3.90257 -7.41683 0.048376 0.153833 -0.171698</acceleration>
          <wrench>0.008498 -1.13175 -2.15088 0 -0 0</wrench>
        </link>
        <link name='right_rear_axle_carrier'>
          <pose frame=''>-0.163233 -0.152174 0.073022 5.4e-05 -0.001574 -0.001103</pose>
          <velocity>0.000761 0.005434 -0.003693 0.084581 3e-06 0.003712</velocity>
          <acceleration>0.736431 2.61007 -7.42403 -2.29552 0.095167 -2.404</acceleration>
          <wrench>0.000736 0.00261 -0.007424 0 -0 0</wrench>
        </link>
        <link name='right_rear_wheel'>
          <pose frame=''>-0.163228 -0.152182 0.073022 1.57085 -0.014872 -0.001104</pose>
          <velocity>8.7e-05 -0.005916 -0.003692 0.081081 -0.000972 0.003557</velocity>
          <acceleration>0.092467 -3.83882 -7.42109 -0.797972 1.39028 2.75142</acceleration>
          <wrench>0.026815 -1.11326 -2.15212 0 -0 0</wrench>
        </link>
        <link name='right_steering_link'>
          <pose frame=''>0.171764 -0.15255 0.073022 5.4e-05 -0.001574 -0.001105</pose>
          <velocity>0.000174 -0.003448 -0.003739 0.084501 -3e-06 0.002273</velocity>
          <acceleration>0.16187 -2.25275 -7.42735 -2.31868 0.091221 3.04025</acceleration>
          <wrench>0.000162 -0.002253 -0.007427 0 -0 0</wrench>
        </link>
      </model>
      <light name='sun'>
        <pose frame=''>0 0 10 0 -0 0</pose>
      </light>
    </state>
    <gui fullscreen='0'>
      <camera name='user_camera'>
        <pose frame=''>16.9147 -12.5953 7.08618 0 0.275643 2.35619</pose>
        <view_controller>orbit</view_controller>
        <projection_type>perspective</projection_type>
      </camera>
    </gui>
  </world>
</sdf>
